Workbook

Sheet INDEX
B3: S.NO. | C3: GOVT. DEPT. | I3: ItemCode | J3: ItemName | K3: Net Weight KG
B4: 1 | C4: IBIX | D4: with ALL COLOURS | F4: White | I4: 1216 D | J4: S.S. SINK S/B SOLITAIRE 16*18*8 | K4: 2.62 | P4: STANDARD | Q4: STANDARD
B5: 2 | C5: ROMAN | F5: Ivory | I5: 1216 D MATT | J5: S.S. SINK S/B SOLITAIRE 16*18*8 MATT | K5: 2.62 | P5: DIAMOND | Q5: ROYAL
B6: 3 | C6: GRAND | F6: Blue | I6: 1217 D | J6: S.S.SINK S/B SOLITAIRE 18*18*8. | K6: 2.72 | P6: FLORA | Q6: ROYAL
B7: 4 | C7: VITRO | D7: with ALL COLOURS | F7: O Blue | I7: 1218 D | J7: S.S.SINK S/B SOLITAIRE 17*20*8 | K7: 2.88 | P7: COBRA | Q7: HI-FLO PRIME
B8: 5 | C8: BLACK PEARL | F8: Green | I8: 1218 D MATT | J8: S.S.SINK S/B SOLITAIRE 17X20X8 (MATT) | K8: 2.88 | P8: BLACK PEARL | Q8: REGAL
F9: M Green | I9: 1220 D | J9: S.S.SINK S/B SOLITAIRE 18*21*8 | K9: 2.98 | P9: GRAND | Q9: FANCY
F10: Pink | I10: 1220 D MATT | J10: S.S.SINK S/B SOLITAIRE 18x21x8 | K10: 2.98 | P10: NOVO | Q10: EDGE
F11: Burgundy | I11: 1222 D | J11: S.S.SINK S/B SOLITAIRE 22*18*8 | K11: 3.2 | P11: LAGOONA | Q11: SUPERB
I12: 1222 D MATT | J12: S.S.SINK S/B SOLITAIRE 22X18X8 | K12: 3.2 | P12: DELTA | Q12: CURVE
B13: 3 IN 1 | C13: FF | D13: TALL | I13: 1223 D | J13: S.S.SINK S/B SOLITAIRE 21*17*8 | K13: 2.98
B14: EROSA | C14: EROSA | F14: 3 in 1 Wall Mixer Telephonic with Crutch & Wall Flange (Hand Shower with 1.5 Mtr PVC Tube)
B15: NOVO | F15: 3 in 1 Wall Mixer Telephonic with Crutch & Wall Flange (Provision For Hand Shower) | I15: 1223-DM | J15: S.S.SINK S/B SOLITAIRE 21*17*8 (MATT) | K15: 2.98
B16: ULTRA | F16: 2 in 1 Telephonic Wall Mixer with Crutch & Flange (Hand Shower with 1.5 Mtr PVC Tube) | I16: 1224 D | J16: S.S.SINK S/B SOLITAIRE 24*18*8 | K16: 3.52
B17: OVIAN | I17: 1224 SD | J17: S.S. SINK 24*18*10 S/B | K17: 3.52
B18: LAGOONA | I18: 1224 SDMAT | J18: S.S. SINK 24*18*10 S/B MATT | K18: 3.52
B19: HELIX | C19: HELIX | I19: 1224 XD | J19: S.S.SINK S/B SOLITAIRE 24*18*9 | K19: 3.72
B20: SAPPHIRE | C20: SAPPHIRE | I20: 1224 XD MATT | J20: S.S.SINK S/B SOLITAIRE 24*18*9 (MATT) | K20: 3.72
B21: B SAPPHIRE | C21: B SAPPHIRE | I21: 1225 D | J21: S.S.SINK S/B SOLITAIRE 24*20*8 | K21: 3.9
B22: STD. (OLD) | C22: STD. (OLD) | I22: 1225 D MATT | J22: S.S.SINK S/B SOLITAIRE 24*20*8 MATT | K22: 3.9
B23: STD. | C23: STD. | I23: 1226 D | J23: S.S.SINK S/B SOLITAIRE 24*24*8 | K23: 4.1
B24: CRYSTAL | C24: CRYSTAL | I24: 1226 D MATT | J24: S.S.SINK S/B SOLITAIRE 24*24*8 (MATT) | K24: 4.1
B25: COBRA | C25: COBRA | I25: 1230 D | J25: S.S SINK S/B+D/B BRONZE 32*20*8 | K25: 3.84
B26: DIAMOND | C26: DIAMOND | I26: 1230 D MATT | J26: S.S SINK S/B+D/B BRONZE 32*20*8 (MATT) | K26: 3.84
B27: IBIX
C28: VITRO | I28: 1232 DMAT | J28: S.S.SINK D/B SOLITAIRE 32*20*8 MATT | K28: 5.85
B29: FLORA | C29: FLORA | I29: 1239 D | J29: S.S. SINK S/B SOLITAIRE 36*18*8 | K29: 4.16
B30: ASTRA | C30: ASTRA | I30: 1239 D MATT | J30: S.S. SINK S/B SOLITAIRE 36*18*8 matt | K30: 4.16
B31: APEX | C31: APEX | I31: 1240 D | J31: S.S.SINK S/B SOLITAIRE 37*18*8 | K31: 4.26
B32: EBON | C32: EBON | I32: 1240-D MATT | J32: S.S.SINK S/B SOLITAIRE matt 37*18*8 | K32: 4.26
B33: BLACK PEARL | C33: BLACK PEARL | I33: 1242 D | J33: S.S.SINK D/B SOLITAIRE 37*18*8 | K33: 5.36
B34: GRAND | C34: GRAND | I34: 1242 D MATT | J34: S.S.SINK D/B SOLITAIRE 37*18*8 MATT | K34: 5.36
B35: ROMAN | I35: 1244 D | J35: S.S.SINK S/B SOLITAIRE 41*20*8 | K35: 5
B36: QUADRA | D36: QUADRA | I36: 1244 D MATT | J36: S.S.SINK S/B SOLITAIRE 41*20*8 (MATT) | K36: 5
B37: DELTA | D37: DELTA | I37: 1250 D | J37: S.S.SINK D/B SOLITAIRE 45*20*8 | K37: 6.82
I38: 1250 D MATT | J38: S.S.SINK D/B SOLITAIRE 45*20*8 (MATT) | K38: 6.82
I39: 1250 SD | J39: S.S.SINK D/B SOLITAIRE 45*20*10 | K39: 7.24
I40: 1250 SD MATT | J40: S.S.SINK D/B SOLITAIRE 45X20X10 | K40: 7.24
I41: 1250 XD | J41: S.S.SINK D/B 45*20*9 (ISI) | K41: 7.24
I42: 1250 XD MATT | J42: S.S.SINK D/B 45*20*9 (ISI) MAT | K42: 7.24
...

Sheet Points
B1: * Prayag | C1: * Pearl
B2: Quadra Series | C2: Edge
B3: Diamond Series | C3: Royal
B4: STANDARD Series Old Handle | C4: Standard
B5: STANDARD Series | C5: Standard
B6: Cobra Series | C6: Eva
B7: Vitro Series | C7: Royal Plus
B8: Black Pearl | C8: Regal
B10: 45833
B11: Black Sapphire | C11: Crystal
C12: Cobra
C13: Helix
B14: Standard (Old Handle) | C14: Standard (New Handle)
C15: Diamond
B16: Flora | C16: Astra
C17: Apex
C18: Ebon
C19: Black Pearl
B20: Delta | C20: 1.3 of Quadra
B21: Ibix | C21: 1.3 of Ovian
B22: Grand | C22: 1.3 of Standard
B23: Roman | C23: 1.3 of Helix
B24: Astra | C24: This New Range Introduced of Same Ryan Range in Fern
B25: Apex | C25: This New Range Introduced of Same Stella Range in Fern

Sheet MASTER
A1: TYPE | B1: SERIES | C1: CAT No. | D1: NAME | E1: OLD MRP | F1: NEW MRP | G1: PACKING | AB1: MRP | AC1: Customised | AD1: correct | AE1: unique
A2: PTMT | B2: Allied | C2: CNS-15 | D2: Concealed Stop Cock Suitable For 15mm Pipe Line with 1/2" Spindle | E2: {=Allied!E3:F4} -> 860 | F2: 1020
A3: PTMT | B3: Allied | C3: CNS-20 | D3: Concealed Stop Cock Suitable For 20mm Pipe Line with 1/2" Spindle | E3: 900 | F3: 1060
A4: PTMT | B4: Quadra | C4: PQ-18 | D4: Concealed Stop Cock (Handle, Sleeve & Flange Only) | E4: {=VLOOKUP(C4,Allied!$C$6:$F1832,{3,4},0)} -> 330 | F4: 360
A5: PTMT | B5: Quadra | C5: 146-Q | D5: Concealed Stop Cock Spindle 15mm & Body 15mm | E5: {=VLOOKUP(C5,Allied!$C$6:$F1832,{3,4},0)} -> 1190 | F5: 1290
A6: PTMT | B6: Quadra | C6: 148-Q | D6: Concealed Stop Cock Spindle 20mm & Body 20mm | E6: {=VLOOKUP(C6,Allied!$C$6:$F1832,{3,4},0)} -> 1230 | F6: 1330
A7: PTMT | B7: Delta | C7: PD-18 | D7: Concealed Stop Cock (Handle, Sleeve & Flange Only) | E7: {=VLOOKUP(C7,Allied!$C$6:$F1832,{3,4},0)} -> 330 | F7: 360
A8: PTMT | B8: Delta | C8: 146-D | D8: Concealed Stop Cock Spindle 15mm & Body 15mm | E8: {=VLOOKUP(C8,Allied!$C$6:$F1832,{3,4},0)} -> 1190 | F8: 1290
A9: PTMT | B9: Delta | C9: 148-D | D9: Concealed Stop Cock Spindle 20mm & Body 20mm | E9: {=VLOOKUP(C9,Allied!$C$6:$F1832,{3,4},0)} -> 1230 | F9: 1330
A10: PTMT | B10: Ibix | C10: PI-18 | D10: Concealed Stop Cock (Handle, Sleeve & Flange Only) | E10: {=VLOOKUP(C10,Allied!$C$6:$F1832,{3,4},0)} -> 330 | F10: 360
A11: PTMT | B11: Ibix | C11: 146-I | D11: Concealed Stop Cock Spindle 15mm & Body 15mm | E11: {=VLOOKUP(C11,Allied!$C$6:$F1832,{3,4},0)} -> 1190 | F11: 1290
A12: PTMT | B12: Ibix | C12: 148-I | D12: Concealed Stop Cock Spindle 20mm & Body 20mm | E12: {=VLOOKUP(C12,Allied!$C$6:$F1832,{3,4},0)} -> 1230 | F12: 1330
A13: PTMT | B13: Ovian | C13: PR-18 | D13: Concealed Stop Cock (Handle, Sleeve & Flange Only) | E13: {=VLOOKUP(C13,Allied!$C$6:$F1832,{3,4},0)} -> 330 | F13: 360
A14: PTMT | B14: Ovian | C14: 146-R | D14: Concealed Stop Cock Spindle 15mm & Body 15mm | E14: {=VLOOKUP(C14,Allied!$C$6:$F1832,{3,4},0)} -> 1190 | F14: 1290
A15: PTMT | B15: Ovian | C15: 148-R | D15: Concealed Stop Cock Spindle 20mm & Body 20mm | E15: {=VLOOKUP(C15,Allied!$C$6:$F1832,{3,4},0)} -> 1230 | F15: 1330
A16: PTMT | B16: Novo | C16: 123-NN | D16: Bib Cock Fancy 15mm (Foam Flow) with Flange | E16: {=VLOOKUP(C16,'NEW PTMT'!$B$4:$E1832,{3,4},0)} -> 298 | F16: 322 | G16: 54 | Z16: =B16&AC16 -> Novo123 | AA16: =B16&AD16 -> NovoBib Cock Fancy with Flange | AB16: =F16 -> 322 | AC16: 123 | AD16: Bib Cock Fancy with Flange | AE16: {=SORT(UNIQUE(AD16:AD1832),1,1)} -> 2 in 1 Telephonic Wall Mixer
A17: PTMT | B17: Novo | C17: 124-N | D17: Bib Cock Long Body 15mm (Foam Flow) with Flange | E17: {=VLOOKUP(C17,'NEW PTMT'!$B$4:$E1832,{3,4},0)} -> 362 | F17: 392 | G17: 33 | Z17: =B17&AC17 -> Novo124 | AA17: =B17&AD17 -> NovoBib Cock Long Body with Flange | AB17: =F17 -> 392 | AC17: 124 | AD17: Bib Cock Long Body with Flange | AE17: 2 Way Angle Cock with Flange
A18: PTMT | B18: Novo | C18: 127-N | D18: Bib Cock Nozzle with Flange | E18: {=VLOOKUP(C18,'NEW PTMT'!$B$4:$E1832,{3,4},0)} -> 332 | F18: 358 | G18: 33 | Z18: =B18&AC18 -> Novo127 | AA18: =B18&AD18 -> NovoBib Cock Nozzle with Flange | AB18: =F18 -> 358 | AC18: 127 | AD18: Bib Cock Nozzle with Flange | AE18: 2 Way Bib Cock with Flange
A19: PTMT | B19: Novo | C19: 129-N | D19: 2 Way Bib Cock Foam Flow with Flange | E19: {=VLOOKUP(C19,'NEW PTMT'!$B$4:$E1832,{3,4},0)} -> 572 | F19: 618 | G19: 28 | Z19: =B19&AC19 -> Novo129 | AA19: =B19&AD19 -> Novo2 Way Bib Cock with Flange | AB19: =F19 -> 618 | AC19: 129 | AD19: 2 Way Bib Cock with Flange | AE19: Angle Cock with Flange
A20: PTMT | B20: Novo | C20: 130-N | D20: Pillar Cock Foam Flow with Flange | E20: {=VLOOKUP(C20,'NEW PTMT'!$B$4:$E1832,{3,4},0)} -> 432 | F20: 468 | G20: 30 | Z20: =B20&AC20 -> Novo130 | AA20: =B20&AD20 -> NovoPillar Cock with Flange | AB20: =F20 -> 468 | AC20: 130 | AD20: Pillar Cock with Flange | AE20: Bib Cock (Foam Flow) with Flange
A21: PTMT | B21: Novo | C21: 132-N | D21: Sink Cock (W/M) Foam Flow with Flange | E21: {=VLOOKUP(C21,'NEW PTMT'!$B$4:$E1832,{3,4},0)} -> 658 | F21: 712 | G21: 13 | Z21: =B21&AC21 -> Novo132 | AA21: =B21&AD21 -> NovoSink Cock (W/M) with Flange | AB21: =F21 -> 712 | AC21: 132 | AD21: Sink Cock (W/M) with Flange | AE21: Bib Cock Fancy (Foam Flow) with Flange
A22: PTMT | B22: Novo | C22: 1322-N | D22: Sink Cock Swan Neck (W/M) Small Spout Foam Flow with Flange | E22: {=VLOOKUP(C22,'NEW PTMT'!$B$4:$E1832,{3,4},0)} -> 632 | F22: 684 | G22: 30 | Z22: =B22&AC22 -> Novo1322 | AA22: =B22&AD22 -> NovoSink Cock Small Spout (W/M) with Flange | AB22: =F22 -> 684 | AC22: 1322 | AD22: Sink Cock Small Spout (W/M) with Flange | AE22: Bib Cock Fancy (Foam Flow) with New Flange & Nipple
A23: PTMT | B23: Novo | C23: 133-N | D23: Sink Cock Swan Neck (T/M) Long Spout Foam Flow with Flange | E23: {=VLOOKUP(C23,'NEW PTMT'!$B$4:$E1832,{3,4},0)} -> 698.0064 | F23: 754 | G23: 13 | Z23: =B23&AC23 -> Novo133 | AA23: =B23&AD23 -> NovoSink Cock Long Spout (T/M) with Flange | AB23: =F23 -> 754 | AC23: 133 | AD23: Sink Cock Long Spout (T/M) with Flange | AE23: Bib Cock Fancy with Flange
A24: PTMT | B24: Novo | C24: 134-N | D24: Sink Mixer Foam Flow with Flange | E24: {=VLOOKUP(C24,'NEW PTMT'!$B$4:$E1832,{3,4},0)} -> 1572 | F24: 1698 | G24: 13 | Z24: =B24&AC24 -> Novo134 | AA24: =B24&AD24 -> NovoSink Mixer with Flange | AB24: =F24 -> 1698 | AC24: 134 | AD24: Sink Mixer with Flange | AE24: Bib Cock Fancy with New Flange & Nipple
A25: PTMT | B25: Novo | C25: 135-N | D25: Wall Mixer Foam Flow with Flange | E25: {=VLOOKUP(C25,'NEW PTMT'!$B$4:$E1832,{3,4},0)} -> 1527.552 | F25: 1648 | G25: 13 | Z25: =B25&AC25 -> Novo135 | AA25: =B25&AD25 -> NovoWall Mixer with Flange | AB25: =F25 -> 1648 | AC25: 135 | AD25: Wall Mixer with Flange | AE25: Bib Cock Long Body (Foam Flow) with Flange
A26: PTMT | B26: Novo | C26: 1374-N | D26: 2 in 1 Telephonic Wall Mixer with Crutch & Hand Shower with 1.5 Mtr Tube | E26: {=VLOOKUP(C26,'NEW PTMT'!$B$4:$E1832,{3,4},0)} -> 2092 | F26: 2258 | Z26: =B26&AC26 -> Novo1374 | AA26: =B26&AD26 -> Novo2 in 1 Telephonic Wall Mixer | AB26: =F26 -> 2258 | AC26: 1374 | AD26: 2 in 1 Telephonic Wall Mixer | AE26: Bib Cock Long Body Foam Flow with Flange
A27: PTMT | B27: Novo | C27: 1375-N | D27: Wall Mixer L Bend Foam Flow with Flange | E27: {=VLOOKUP(C27,'NEW PTMT'!$B$4:$E1832,{3,4},0)} -> 1784 | F27: 1928 | G27: 6 | Z27: =B27&AC27 -> Novo1375 | AA27: =B27&AD27 -> NovoWall Mixer L Bend with Flange | AB27: =F27 -> 1928 | AC27: 1375 | AD27: Wall Mixer L Bend with Flange | AE27: Bib Cock Long Body with Flange
A28: PTMT | B28: Novo | C28: 144-N | D28: Angle Cock with Flange | E28: {=VLOOKUP(C28,'NEW PTMT'!$B$4:$E1832,{3,4},0)} -> 272 | F28: 294 | G28: 66 | Z28: =B28&AC28 -> Novo144 | AA28: =B28&AD28 -> NovoAngle Cock with Flange | AB28: =F28 -> 294 | AC28: 144 | AD28: Angle Cock with Flange | AE28: Bib Cock Nozzle with Flange
A29: PTMT | B29: Novo | C29: 145-N | D29: 2 Way Angle Cock Foam Flow with Flange | E29: {=VLOOKUP(C29,'NEW PTMT'!$B$4:$E1832,{3,4},0)} -> 507.96 | F29: 548 | G29: 35 | Z29: =B29&AC29 -> Novo145 | AA29: =B29&AD29 -> Novo2 Way Angle Cock with Flange | AB29: =F29 -> 548 | AC29: 145 | AD29: 2 Way Angle Cock with Flange | AE29: Bib Cock Standard (Female) with Flange
A30: PTMT | B30: Novo | C30: 147-N | D30: Pillar Cock Swan Neck Square Spout Foam Flow with Flange | E30: {=VLOOKUP(C30,'NEW PTMT'!$B$4:$E1832,{3,4},0)} -> 711.96 | F30: 768 | G30: 30 | Z30: =B30&AC30 -> Novo147 | AA30: =B30&AD30 -> NovoPillar Cock Swan Neck (T/M) with Flange | AB30: =F30 -> 768 | AC30: 147 | AD30: Pillar Cock Swan Neck (T/M) with Flange | AE30: Bib Cock Standard 20mm with Flange
A31: PTMT | B31: Ultra | C31: 123-U | D31: Bib Cock Fancy 15mm (Foam Flow) with Flange | E31: {=VLOOKUP(C31,'NEW PTMT'!$B$4:$E1832,{3,4},0)} -> 395.76 | F31: 426 | G31: 33 | Z31: =B31&AC31 -> Ultra123 | AA31: =B31&AD31 -> UltraBib Cock Fancy with Flange | AB31: =F31 -> 426 | AC31: 123 | AD31: Bib Cock Fancy with Flange | AE31: Bib Cock with Flange
A32: PTMT | B32: Ultra | C32: 124-U | D32: Bib Cock Long Body 15mm (Foam Flow) with Flange | E32: {=VLOOKUP(C32,'NEW PTMT'!$B$4:$E1832,{3,4},0)} -> 485.8464 | F32: 526 | G32: 33 | Z32: =B32&AC32 -> Ultra124 | AA32: =B32&AD32 -> UltraBib Cock Long Body with Flange | AB32: =F32 -> 526 | AC32: 124 | AD32: Bib Cock Long Body with Flange | AE32: Center Hole Basin Mixer
A33: PTMT | B33: Ultra | C33: 127-U | D33: Bib Cock Nozzle with Flange | E33: {=VLOOKUP(C33,'NEW PTMT'!$B$4:$E1832,{3,4},0)} -> 422.1984 | F33: 456 | G33: 33 | Z33: =B33&AC33 -> Ultra127 | AA33: =B33&AD33 -> UltraBib Cock Nozzle with Flange | AB33: =F33 -> 456 | AC33: 127 | AD33: Bib Cock Nozzle with Flange | AE33: Concealed Stop Cock 15mm
A34: PTMT | B34: Ultra | C34: 129-U | D34: 2 Way Bib Cock (Foam Flow) with Flange | E34: {=VLOOKUP(C34,'NEW PTMT'!$B$4:$E1832,{3,4},0)} -> 732 | F34: 792 | G34: 24 | Z34: =B34&AC34 -> Ultra129 | AA34: =B34&AD34 -> Ultra2 Way Bib Cock with Flange | AB34: =F34 -> 792 | AC34: 129 | AD34: 2 Way Bib Cock with Flange | AE34: Concealed Stop Cock 15mm with Brass Body
A35: PTMT | B35: Ultra | C35: 130-U | D35: Pillar Cock (Foam Flow) with Flange | E35: {=VLOOKUP(C35,'NEW PTMT'!$B$4:$E1832,{3,4},0)} -> 497.76 | F35: 538 | G35: 30 | Z35: =B35&AC35 -> Ultra130 | AA35: =B35&AD35 -> UltraPillar Cock with Flange | AB35: =F35 -> 538 | AC35: 130 | AD35: Pillar Cock with Flange | AE35: Concealed Stop Cock 20mm
A36: PTMT | B36: Ultra | C36: 132-U | D36: Sink Cock (W/M) (Foam Flow) with Flange | E36: {=VLOOKUP(C36,'NEW PTMT'!$B$4:$E1832,{3,4},0)} -> 784 | F36: 848 | G36: 13 | Z36: =B36&AC36 -> Ultra132 | AA36: =B36&AD36 -> UltraSink Cock (W/M) with Flange | AB36: =F36 -> 848 | AC36: 132 | AD36: Sink Cock (W/M) with Flange | AE36: Concealed Stop Cock 20mm with Brass Body
A37: PTMT | B37: Ultra | C37: 1322-U | D37: Sink Cock Swan Neck (W/M) Small Spout Foam Flow with Flange | E37: {=VLOOKUP(C37,'NEW PTMT'!$B$4:$E1832,{3,4},0)} -> 738.3168 | F37: 798 | G37: 30 | Z37: =B37&AC37 -> Ultra1322 | AA37: =B37&AD37 -> UltraSink Cock Small Spout (W/M) with Flange | AB37: =F37 -> 798 | AC37: 1322 | AD37: Sink Cock Small Spout (W/M) with Flange | AE37: Pillar Cock (Foam Flow) with Flange
A38: PTMT | B38: Ultra | C38: 133-U | D38: Sink Cock Swan Neck (T/M) Long Spout Foam Flow with Flange | E38: {=VLOOKUP(C38,'NEW PTMT'!$B$4:$E1832,{3,4},0)} -> 784 | F38: 848 | G38: 13 | Z38: =B38&AC38 -> Ultra133 | AA38: =B38&AD38 -> UltraSink Cock Long Spout (T/M) with Flange | AB38: =F38 -> 848 | AC38: 133 | AD38: Sink Cock Long Spout (T/M) with Flange | AE38: Pillar Cock 12" Tall Height with Flange
A39: PTMT | B39: Ultra | C39: 134-U | D39: Sink Mixer Foam Flow with Flange | E39: {=VLOOKUP(C39,'NEW PTMT'!$B$4:$E1832,{3,4},0)} -> 1632 | F39: 1764 | G39: 13 | Z39: =B39&AC39 -> Ultra134 | AA39: =B39&AD39 -> UltraSink Mixer with Flange | AB39: =F39 -> 1764 | AC39: 134 | AD39: Sink Mixer with Flange | AE39: Pillar Cock Fancy (R.H.) with Flange
A40: PTMT | B40: Ultra | C40: 135-U | D40: Wall Mixer Foam Flow with Flange | E40: {=VLOOKUP(C40,'NEW PTMT'!$B$4:$E1832,{3,4},0)} -> 1572 | F40: 1698 | G40: 13 | Z40: =B40&AC40 -> Ultra135 | AA40: =B40&AD40 -> UltraWall Mixer with Flange | AB40: =F40 -> 1698 | AC40: 135 | AD40: Wall Mixer with Flange | AE40: Pillar Cock Fancy with Flange
...

Sheet PTMT RANGE
F1: 1.1 | G1: 1.05
D2: SPECIAL RANGES
D3: =COUNT(D5:D999) -> 19 | E3: =COUNT(E5:E999) -> 18 | F3: =COUNT(F5:F999) -> 16 | G3: =COUNT(G5:G999) -> 18 | H3: =COUNT(H5:H999) -> 17 | I3: =COUNT(I5:I999) -> 17 | J3: =COUNT(J5:J999) -> 17 | K3: =COUNT(K5:K999) -> 18 | ... AC3: =COUNT(AC5:AC999) -> 3
A4: S. No. | B4: Item Code | C4: Item Name | D4: Delta | E4: Ibix | F4: Vitro | G4: Flora | H4: Astra | I4: Apex | J4: Ebon | K4: Black Pearl | L4: Grand | M4: Roman | N4: Novo | O4: Ultra | P4: Quadra | Q4: Ovian | R4: Lagoona | S4: Standard (Old Handle) | T4: Standard (New Handle) | U4: Diamond | V4: Sapphire | W4: Crystal | X4: Helix | Y4: Black Sapphire | Z4: Cobra | AA4: Erosa | AB4: Luxor | AC4: Glory
A5: 1 | B5: 121 | C5: =VLOOKUP(B5,MASTER!$AC$16:$AD999,2,0) -> Bib Cock with Flange | D5: =IFERROR(VLOOKUP(D$4&$B5,MASTER!$Z$16:$AB999,3,0),"") | E5: =IFERROR(VLOOKUP(E$4&$B5,MASTER!$Z$16:$AB999,3,0),"") -> 432 | F5: =IFERROR(VLOOKUP(F$4&$B5,MASTER!$Z$16:$AB999,3,0),"") -> 262 | G5: =IFERROR(VLOOKUP(G$4&$B5,MASTER!$Z$16:$AB999,3,0),"") -> 244 | H5: =IFERROR(VLOOKUP(H$4&$B5,MASTER!$Z$16:$AB999,3,0),"") -> 244 | I5: =IFERROR(VLOOKUP(I$4&$B5,MASTER!$Z$16:$AB999,3,0),"") -> 244 | J5: =IFERROR(VLOOKUP(J$4&$B5,MASTER!$Z$16:$AB999,3,0),"") -> 244 | K5: =IFERROR(VLOOKUP(K$4&$B5,MASTER!$Z$16:$AB999,3,0),"") -> 244 | ... AC5: =IFERROR(VLOOKUP(AC$4&$B5,MASTER!$Z$16:$AB999,3,0),"") -> 148
A6: 2 | B6: 121-F | C6: =VLOOKUP(B6,MASTER!$AC$16:$AD999,2,0) -> Bib Cock (Foam Flow) with Flange | D6: =IFERROR(VLOOKUP(D$4&$B6,MASTER!$Z$16:$AB999,3,0),"") | E6: =IFERROR(VLOOKUP(E$4&$B6,MASTER!$Z$16:$AB999,3,0),"") | F6: =IFERROR(VLOOKUP(F$4&$B6,MASTER!$Z$16:$AB999,3,0),"") -> 274 | G6: =IFERROR(VLOOKUP(G$4&$B6,MASTER!$Z$16:$AB999,3,0),"") -> 256 | H6: =IFERROR(VLOOKUP(H$4&$B6,MASTER!$Z$16:$AB999,3,0),"") -> 258 | I6: =IFERROR(VLOOKUP(I$4&$B6,MASTER!$Z$16:$AB999,3,0),"") -> 258 | J6: =IFERROR(VLOOKUP(J$4&$B6,MASTER!$Z$16:$AB999,3,0),"") -> 258 | K6: =IFERROR(VLOOKUP(K$4&$B6,MASTER!$Z$16:$AB999,3,0),"") -> 256 | ... AC6: =IFERROR(VLOOKUP(AC$4&$B6,MASTER!$Z$16:$AB999,3,0),"")
A7: 3 | B7: 122 | C7: =VLOOKUP(B7,MASTER!$AC$16:$AD999,2,0) -> Bib Cock (Foam Flow) with Flange | D7: =IFERROR(VLOOKUP(D$4&$B7,MASTER!$Z$16:$AB999,3,0),"") | E7: =IFERROR(VLOOKUP(E$4&$B7,MASTER!$Z$16:$AB999,3,0),"") -> 472 | F7: =IFERROR(VLOOKUP(F$4&$B7,MASTER!$Z$16:$AB999,3,0),"") | G7: =IFERROR(VLOOKUP(G$4&$B7,MASTER!$Z$16:$AB999,3,0),"") | H7: =IFERROR(VLOOKUP(H$4&$B7,MASTER!$Z$16:$AB999,3,0),"") | I7: =IFERROR(VLOOKUP(I$4&$B7,MASTER!$Z$16:$AB999,3,0),"") | J7: =IFERROR(VLOOKUP(J$4&$B7,MASTER!$Z$16:$AB999,3,0),"") | K7: =IFERROR(VLOOKUP(K$4&$B7,MASTER!$Z$16:$AB999,3,0),"") | ... AC7: =IFERROR(VLOOKUP(AC$4&$B7,MASTER!$Z$16:$AB999,3,0),"")
A8: 4 | B8: 123 | C8: =VLOOKUP(B8,MASTER!$AC$16:$AD999,2,0) -> Bib Cock Fancy with Flange | D8: =IFERROR(VLOOKUP(D$4&$B8,MASTER!$Z$16:$AB999,3,0),"") -> 504 | E8: =IFERROR(VLOOKUP(E$4&$B8,MASTER!$Z$16:$AB999,3,0),"") -> 514 | F8: =IFERROR(VLOOKUP(F$4&$B8,MASTER!$Z$16:$AB999,3,0),"") | G8: =IFERROR(VLOOKUP(G$4&$B8,MASTER!$Z$16:$AB999,3,0),"") | H8: =IFERROR(VLOOKUP(H$4&$B8,MASTER!$Z$16:$AB999,3,0),"") | I8: =IFERROR(VLOOKUP(I$4&$B8,MASTER!$Z$16:$AB999,3,0),"") | J8: =IFERROR(VLOOKUP(J$4&$B8,MASTER!$Z$16:$AB999,3,0),"") | K8: =IFERROR(VLOOKUP(K$4&$B8,MASTER!$Z$16:$AB999,3,0),"") | ... AC8: =IFERROR(VLOOKUP(AC$4&$B8,MASTER!$Z$16:$AB999,3,0),"")
A9: 5 | B9: 123-F | C9: =VLOOKUP(B9,MASTER!$AC$16:$AD999,2,0) -> Bib Cock Fancy (Foam Flow) with Flange | D9: =IFERROR(VLOOKUP(D$4&$B9,MASTER!$Z$16:$AB999,3,0),"") | E9: =IFERROR(VLOOKUP(E$4&$B9,MASTER!$Z$16:$AB999,3,0),"") | F9: =IFERROR(VLOOKUP(F$4&$B9,MASTER!$Z$16:$AB999,3,0),"") | G9: =IFERROR(VLOOKUP(G$4&$B9,MASTER!$Z$16:$AB999,3,0),"") | H9: =IFERROR(VLOOKUP(H$4&$B9,MASTER!$Z$16:$AB999,3,0),"") | I9: =IFERROR(VLOOKUP(I$4&$B9,MASTER!$Z$16:$AB999,3,0),"") | J9: =IFERROR(VLOOKUP(J$4&$B9,MASTER!$Z$16:$AB999,3,0),"") | K9: =IFERROR(VLOOKUP(K$4&$B9,MASTER!$Z$16:$AB999,3,0),"") | ... AC9: =IFERROR(VLOOKUP(AC$4&$B9,MASTER!$Z$16:$AB999,3,0),"")
A10: 6 | B10: 123-N | C10: =VLOOKUP(B10,MASTER!$AC$16:$AD999,2,0) -> Bib Cock Fancy with New Flange & Nipple | D10: =IFERROR(VLOOKUP(D$4&$B10,MASTER!$Z$16:$AB999,3,0),"") | E10: =IFERROR(VLOOKUP(E$4&$B10,MASTER!$Z$16:$AB999,3,0),"") | F10: =IFERROR(VLOOKUP(F$4&$B10,MASTER!$Z$16:$AB999,3,0),"") | G10: =IFERROR(VLOOKUP(G$4&$B10,MASTER!$Z$16:$AB999,3,0),"") | H10: =IFERROR(VLOOKUP(H$4&$B10,MASTER!$Z$16:$AB999,3,0),"") | I10: =IFERROR(VLOOKUP(I$4&$B10,MASTER!$Z$16:$AB999,3,0),"") | J10: =IFERROR(VLOOKUP(J$4&$B10,MASTER!$Z$16:$AB999,3,0),"") | K10: =IFERROR(VLOOKUP(K$4&$B10,MASTER!$Z$16:$AB999,3,0),"") | ... AC10: =IFERROR(VLOOKUP(AC$4&$B10,MASTER!$Z$16:$AB999,3,0),"")
A11: 7 | B11: 124 | C11: =VLOOKUP(B11,MASTER!$AC$16:$AD999,2,0) -> Bib Cock Long Body with Flange | D11: =IFERROR(VLOOKUP(D$4&$B11,MASTER!$Z$16:$AB999,3,0),"") -> 618 | E11: =IFERROR(VLOOKUP(E$4&$B11,MASTER!$Z$16:$AB999,3,0),"") -> 534 | F11: =IFERROR(VLOOKUP(F$4&$B11,MASTER!$Z$16:$AB999,3,0),"") -> 362 | G11: =IFERROR(VLOOKUP(G$4&$B11,MASTER!$Z$16:$AB999,3,0),"") -> 322 | H11: =IFERROR(VLOOKUP(H$4&$B11,MASTER!$Z$16:$AB999,3,0),"") -> 318 | I11: =IFERROR(VLOOKUP(I$4&$B11,MASTER!$Z$16:$AB999,3,0),"") -> 318 | J11: =IFERROR(VLOOKUP(J$4&$B11,MASTER!$Z$16:$AB999,3,0),"") -> 318 | K11: =IFERROR(VLOOKUP(K$4&$B11,MASTER!$Z$16:$AB999,3,0),"") -> 322 | ... AC11: =IFERROR(VLOOKUP(AC$4&$B11,MASTER!$Z$16:$AB999,3,0),"") -> 178
A12: 8 | B12: 124-F | C12: =VLOOKUP(B12,MASTER!$AC$16:$AD999,2,0) -> Bib Cock Long Body (Foam Flow) with Flange | D12: =IFERROR(VLOOKUP(D$4&$B12,MASTER!$Z$16:$AB999,3,0),"") | E12: =IFERROR(VLOOKUP(E$4&$B12,MASTER!$Z$16:$AB999,3,0),"") | F12: =IFERROR(VLOOKUP(F$4&$B12,MASTER!$Z$16:$AB999,3,0),"") | G12: =IFERROR(VLOOKUP(G$4&$B12,MASTER!$Z$16:$AB999,3,0),"") -> 338 | H12: =IFERROR(VLOOKUP(H$4&$B12,MASTER!$Z$16:$AB999,3,0),"") | I12: =IFERROR(VLOOKUP(I$4&$B12,MASTER!$Z$16:$AB999,3,0),"") | J12: =IFERROR(VLOOKUP(J$4&$B12,MASTER!$Z$16:$AB999,3,0),"") | K12: =IFERROR(VLOOKUP(K$4&$B12,MASTER!$Z$16:$AB999,3,0),"") -> 338 | ... AC12: =IFERROR(VLOOKUP(AC$4&$B12,MASTER!$Z$16:$AB999,3,0),"")
A13: 9 | B13: 125 | C13: =VLOOKUP(B13,MASTER!$AC$16:$AD999,2,0) -> Bib Cock Standard 20mm with Flange | D13: =IFERROR(VLOOKUP(D$4&$B13,MASTER!$Z$16:$AB999,3,0),"") | E13: =IFERROR(VLOOKUP(E$4&$B13,MASTER!$Z$16:$AB999,3,0),"") | F13: =IFERROR(VLOOKUP(F$4&$B13,MASTER!$Z$16:$AB999,3,0),"") | G13: =IFERROR(VLOOKUP(G$4&$B13,MASTER!$Z$16:$AB999,3,0),"") | H13: =IFERROR(VLOOKUP(H$4&$B13,MASTER!$Z$16:$AB999,3,0),"") | I13: =IFERROR(VLOOKUP(I$4&$B13,MASTER!$Z$16:$AB999,3,0),"") | J13: =IFERROR(VLOOKUP(J$4&$B13,MASTER!$Z$16:$AB999,3,0),"") | K13: =IFERROR(VLOOKUP(K$4&$B13,MASTER!$Z$16:$AB999,3,0),"") | ... AC13: =IFERROR(VLOOKUP(AC$4&$B13,MASTER!$Z$16:$AB999,3,0),"")
A14: 10 | B14: 127 | C14: =VLOOKUP(B14,MASTER!$AC$16:$AD999,2,0) -> Bib Cock Nozzle with Flange | D14: =IFERROR(VLOOKUP(D$4&$B14,MASTER!$Z$16:$AB999,3,0),"") -> 526 | E14: =IFERROR(VLOOKUP(E$4&$B14,MASTER!$Z$16:$AB999,3,0),"") | F14: =IFERROR(VLOOKUP(F$4&$B14,MASTER!$Z$16:$AB999,3,0),"") -> 308 | G14: =IFERROR(VLOOKUP(G$4&$B14,MASTER!$Z$16:$AB999,3,0),"") -> 294 | H14: =IFERROR(VLOOKUP(H$4&$B14,MASTER!$Z$16:$AB999,3,0),"") -> 294 | I14: =IFERROR(VLOOKUP(I$4&$B14,MASTER!$Z$16:$AB999,3,0),"") -> 294 | J14: =IFERROR(VLOOKUP(J$4&$B14,MASTER!$Z$16:$AB999,3,0),"") -> 294 | K14: =IFERROR(VLOOKUP(K$4&$B14,MASTER!$Z$16:$AB999,3,0),"") -> 294 | ... AC14: =IFERROR(VLOOKUP(AC$4&$B14,MASTER!$Z$16:$AB999,3,0),"")
A15: 11 | B15: 129 | C15: =VLOOKUP(B15,MASTER!$AC$16:$AD999,2,0) -> 2 Way Bib Cock with Flange | D15: =IFERROR(VLOOKUP(D$4&$B15,MASTER!$Z$16:$AB999,3,0),"") -> 946 | E15: =IFERROR(VLOOKUP(E$4&$B15,MASTER!$Z$16:$AB999,3,0),"") -> 912 | F15: =IFERROR(VLOOKUP(F$4&$B15,MASTER!$Z$16:$AB999,3,0),"") -> 558 | G15: =IFERROR(VLOOKUP(G$4&$B15,MASTER!$Z$16:$AB999,3,0),"") -> 492 | H15: =IFERROR(VLOOKUP(H$4&$B15,MASTER!$Z$16:$AB999,3,0),"") -> 492 | I15: =IFERROR(VLOOKUP(I$4&$B15,MASTER!$Z$16:$AB999,3,0),"") -> 492 | J15: =IFERROR(VLOOKUP(J$4&$B15,MASTER!$Z$16:$AB999,3,0),"") -> 492 | K15: =IFERROR(VLOOKUP(K$4&$B15,MASTER!$Z$16:$AB999,3,0),"") -> 492 | ... AC15: =IFERROR(VLOOKUP(AC$4&$B15,MASTER!$Z$16:$AB999,3,0),"")
A16: 12 | B16: 130 | C16: =VLOOKUP(B16,MASTER!$AC$16:$AD999,2,0) -> Pillar Cock with Flange | D16: =IFERROR(VLOOKUP(D$4&$B16,MASTER!$Z$16:$AB999,3,0),"") -> 678 | E16: =IFERROR(VLOOKUP(E$4&$B16,MASTER!$Z$16:$AB999,3,0),"") -> 652 | F16: =IFERROR(VLOOKUP(F$4&$B16,MASTER!$Z$16:$AB999,3,0),"") -> 358 | G16: =IFERROR(VLOOKUP(G$4&$B16,MASTER!$Z$16:$AB999,3,0),"") -> 338 | H16: =IFERROR(VLOOKUP(H$4&$B16,MASTER!$Z$16:$AB999,3,0),"") -> 338 | I16: =IFERROR(VLOOKUP(I$4&$B16,MASTER!$Z$16:$AB999,3,0),"") -> 338 | J16: =IFERROR(VLOOKUP(J$4&$B16,MASTER!$Z$16:$AB999,3,0),"") -> 338 | K16: =IFERROR(VLOOKUP(K$4&$B16,MASTER!$Z$16:$AB999,3,0),"") -> 338 | ... AC16: =IFERROR(VLOOKUP(AC$4&$B16,MASTER!$Z$16:$AB999,3,0),"")
A17: 13 | B17: 131 | C17: =VLOOKUP(B17,MASTER!$AC$16:$AD999,2,0) -> Pillar Cock 12" Tall Height with Flange | D17: =IFERROR(VLOOKUP(D$4&$B17,MASTER!$Z$16:$AB999,3,0),"") -> 794 | E17: =IFERROR(VLOOKUP(E$4&$B17,MASTER!$Z$16:$AB999,3,0),"") -> 652 | F17: =IFERROR(VLOOKUP(F$4&$B17,MASTER!$Z$16:$AB999,3,0),"") | G17: =IFERROR(VLOOKUP(G$4&$B17,MASTER!$Z$16:$AB999,3,0),"") | H17: =IFERROR(VLOOKUP(H$4&$B17,MASTER!$Z$16:$AB999,3,0),"") | I17: =IFERROR(VLOOKUP(I$4&$B17,MASTER!$Z$16:$AB999,3,0),"") | J17: =IFERROR(VLOOKUP(J$4&$B17,MASTER!$Z$16:$AB999,3,0),"") | K17: =IFERROR(VLOOKUP(K$4&$B17,MASTER!$Z$16:$AB999,3,0),"") | ... AC17: =IFERROR(VLOOKUP(AC$4&$B17,MASTER!$Z$16:$AB999,3,0),"")
A18: 14 | B18: 1311 | C18: =VLOOKUP(B18,MASTER!$AC$16:$AD999,2,0) -> Pillar Cock Fancy (R.H.) with Flange | D18: =IFERROR(VLOOKUP(D$4&$B18,MASTER!$Z$16:$AB999,3,0),"") | E18: =IFERROR(VLOOKUP(E$4&$B18,MASTER!$Z$16:$AB999,3,0),"") | F18: =IFERROR(VLOOKUP(F$4&$B18,MASTER!$Z$16:$AB999,3,0),"") | G18: =IFERROR(VLOOKUP(G$4&$B18,MASTER!$Z$16:$AB999,3,0),"") | H18: =IFERROR(VLOOKUP(H$4&$B18,MASTER!$Z$16:$AB999,3,0),"") | I18: =IFERROR(VLOOKUP(I$4&$B18,MASTER!$Z$16:$AB999,3,0),"") | J18: =IFERROR(VLOOKUP(J$4&$B18,MASTER!$Z$16:$AB999,3,0),"") | K18: =IFERROR(VLOOKUP(K$4&$B18,MASTER!$Z$16:$AB999,3,0),"") | ... AC18: =IFERROR(VLOOKUP(AC$4&$B18,MASTER!$Z$16:$AB999,3,0),"")
A19: 15 | B19: 132 | C19: =VLOOKUP(B19,MASTER!$AC$16:$AD999,2,0) -> Sink Cock (W/M) with Flange | D19: =IFERROR(VLOOKUP(D$4&$B19,MASTER!$Z$16:$AB999,3,0),"") -> 1018 | E19: =IFERROR(VLOOKUP(E$4&$B19,MASTER!$Z$16:$AB999,3,0),"") -> 964 | F19: =IFERROR(VLOOKUP(F$4&$B19,MASTER!$Z$16:$AB999,3,0),"") -> 726 | G19: =IFERROR(VLOOKUP(G$4&$B19,MASTER!$Z$16:$AB999,3,0),"") -> 676 | H19: =IFERROR(VLOOKUP(H$4&$B19,MASTER!$Z$16:$AB999,3,0),"") -> 676 | I19: =IFERROR(VLOOKUP(I$4&$B19,MASTER!$Z$16:$AB999,3,0),"") -> 676 | J19: =IFERROR(VLOOKUP(J$4&$B19,MASTER!$Z$16:$AB999,3,0),"") -> 676 | K19: =IFERROR(VLOOKUP(K$4&$B19,MASTER!$Z$16:$AB999,3,0),"") -> 676 | ... AC19: =IFERROR(VLOOKUP(AC$4&$B19,MASTER!$Z$16:$AB999,3,0),"")
A20: 16 | B20: 1322 | C20: =VLOOKUP(B20,MASTER!$AC$16:$AD999,2,0) -> Sink Cock Small Spout (W/M) with Flange | D20: =IFERROR(VLOOKUP(D$4&$B20,MASTER!$Z$16:$AB999,3,0),"") -> 968 | E20: =IFERROR(VLOOKUP(E$4&$B20,MASTER!$Z$16:$AB999,3,0),"") -> 986 | F20: =IFERROR(VLOOKUP(F$4&$B20,MASTER!$Z$16:$AB999,3,0),"") -> 662 | G20: =IFERROR(VLOOKUP(G$4&$B20,MASTER!$Z$16:$AB999,3,0),"") -> 622 | H20: =IFERROR(VLOOKUP(H$4&$B20,MASTER!$Z$16:$AB999,3,0),"") -> 622 | I20: =IFERROR(VLOOKUP(I$4&$B20,MASTER!$Z$16:$AB999,3,0),"") -> 622 | J20: =IFERROR(VLOOKUP(J$4&$B20,MASTER!$Z$16:$AB999,3,0),"") -> 622 | K20: =IFERROR(VLOOKUP(K$4&$B20,MASTER!$Z$16:$AB999,3,0),"") -> 622 | ... AC20: =IFERROR(VLOOKUP(AC$4&$B20,MASTER!$Z$16:$AB999,3,0),"")
A21: 17 | B21: 133 | C21: =VLOOKUP(B21,MASTER!$AC$16:$AD999,2,0) -> Sink Cock Long Spout (T/M) with Flange | D21: =IFERROR(VLOOKUP(D$4&$B21,MASTER!$Z$16:$AB999,3,0),"") -> 1016 | E21: =IFERROR(VLOOKUP(E$4&$B21,MASTER!$Z$16:$AB999,3,0),"") -> 986 | F21: =IFERROR(VLOOKUP(F$4&$B21,MASTER!$Z$16:$AB999,3,0),"") -> 726 | G21: =IFERROR(VLOOKUP(G$4&$B21,MASTER!$Z$16:$AB999,3,0),"") -> 698 | H21: =IFERROR(VLOOKUP(H$4&$B21,MASTER!$Z$16:$AB999,3,0),"") -> 698 | I21: =IFERROR(VLOOKUP(I$4&$B21,MASTER!$Z$16:$AB999,3,0),"") -> 698 | J21: =IFERROR(VLOOKUP(J$4&$B21,MASTER!$Z$16:$AB999,3,0),"") -> 698 | K21: =IFERROR(VLOOKUP(K$4&$B21,MASTER!$Z$16:$AB999,3,0),"") -> 698 | ... AC21: =IFERROR(VLOOKUP(AC$4&$B21,MASTER!$Z$16:$AB999,3,0),"")
A22: 18 | B22: 134 | C22: =VLOOKUP(B22,MASTER!$AC$16:$AD999,2,0) -> Sink Mixer with Flange | D22: =IFERROR(VLOOKUP(D$4&$B22,MASTER!$Z$16:$AB999,3,0),"") -> 2048 | E22: =IFERROR(VLOOKUP(E$4&$B22,MASTER!$Z$16:$AB999,3,0),"") | F22: =IFERROR(VLOOKUP(F$4&$B22,MASTER!$Z$16:$AB999,3,0),"") -> 1364 | G22: =IFERROR(VLOOKUP(G$4&$B22,MASTER!$Z$16:$AB999,3,0),"") -> 1364 | H22: =IFERROR(VLOOKUP(H$4&$B22,MASTER!$Z$16:$AB999,3,0),"") -> 1364 | I22: =IFERROR(VLOOKUP(I$4&$B22,MASTER!$Z$16:$AB999,3,0),"") -> 1364 | J22: =IFERROR(VLOOKUP(J$4&$B22,MASTER!$Z$16:$AB999,3,0),"") -> 1364 | K22: =IFERROR(VLOOKUP(K$4&$B22,MASTER!$Z$16:$AB999,3,0),"") -> 1364 | ... AC22: =IFERROR(VLOOKUP(AC$4&$B22,MASTER!$Z$16:$AB999,3,0),"")
A23: 19 | B23: 135 | C23: =VLOOKUP(B23,MASTER!$AC$16:$AD999,2,0) -> Wall Mixer with Flange | D23: =IFERROR(VLOOKUP(D$4&$B23,MASTER!$Z$16:$AB999,3,0),"") -> 2048 | E23: =IFERROR(VLOOKUP(E$4&$B23,MASTER!$Z$16:$AB999,3,0),"") | F23: =IFERROR(VLOOKUP(F$4&$B23,MASTER!$Z$16:$AB999,3,0),"") -> 1258 | G23: =IFERROR(VLOOKUP(G$4&$B23,MASTER!$Z$16:$AB999,3,0),"") -> 1306 | H23: =IFERROR(VLOOKUP(H$4&$B23,MASTER!$Z$16:$AB999,3,0),"") -> 1306 | I23: =IFERROR(VLOOKUP(I$4&$B23,MASTER!$Z$16:$AB999,3,0),"") -> 1306 | J23: =IFERROR(VLOOKUP(J$4&$B23,MASTER!$Z$16:$AB999,3,0),"") -> 1306 | K23: =IFERROR(VLOOKUP(K$4&$B23,MASTER!$Z$16:$AB999,3,0),"") -> 1306 | ... AC23: =IFERROR(VLOOKUP(AC$4&$B23,MASTER!$Z$16:$AB999,3,0),"")
A24: 20 | B24: 1374 | C24: =VLOOKUP(B24,MASTER!$AC$16:$AD999,2,0) -> 2 in 1 Telephonic Wall Mixer | D24: =IFERROR(VLOOKUP(D$4&$B24,MASTER!$Z$16:$AB999,3,0),"") -> 2832 | E24: =IFERROR(VLOOKUP(E$4&$B24,MASTER!$Z$16:$AB999,3,0),"") -> 2798 | F24: =IFERROR(VLOOKUP(F$4&$B24,MASTER!$Z$16:$AB999,3,0),"") | G24: =IFERROR(VLOOKUP(G$4&$B24,MASTER!$Z$16:$AB999,3,0),"") -> 2038 | H24: =IFERROR(VLOOKUP(H$4&$B24,MASTER!$Z$16:$AB999,3,0),"") -> 2038 | I24: =IFERROR(VLOOKUP(I$4&$B24,MASTER!$Z$16:$AB999,3,0),"") -> 2038 | J24: =IFERROR(VLOOKUP(J$4&$B24,MASTER!$Z$16:$AB999,3,0),"") -> 2038 | K24: =IFERROR(VLOOKUP(K$4&$B24,MASTER!$Z$16:$AB999,3,0),"") -> 2038 | ... AC24: =IFERROR(VLOOKUP(AC$4&$B24,MASTER!$Z$16:$AB999,3,0),"")
A25: 21 | B25: 1375 | C25: =VLOOKUP(B25,MASTER!$AC$16:$AD999,2,0) -> Wall Mixer L Bend with Flange | D25: =IFERROR(VLOOKUP(D$4&$B25,MASTER!$Z$16:$AB999,3,0),"") -> 2498 | E25: =IFERROR(VLOOKUP(E$4&$B25,MASTER!$Z$16:$AB999,3,0),"") -> 2476 | F25: =IFERROR(VLOOKUP(F$4&$B25,MASTER!$Z$16:$AB999,3,0),"") -> 1648 | G25: =IFERROR(VLOOKUP(G$4&$B25,MASTER!$Z$16:$AB999,3,0),"") -> 1708 | H25: =IFERROR(VLOOKUP(H$4&$B25,MASTER!$Z$16:$AB999,3,0),"") -> 1708 | I25: =IFERROR(VLOOKUP(I$4&$B25,MASTER!$Z$16:$AB999,3,0),"") -> 1708 | J25: =IFERROR(VLOOKUP(J$4&$B25,MASTER!$Z$16:$AB999,3,0),"") -> 1708 | K25: =IFERROR(VLOOKUP(K$4&$B25,MASTER!$Z$16:$AB999,3,0),"") -> 1708 | ... AC25: =IFERROR(VLOOKUP(AC$4&$B25,MASTER!$Z$16:$AB999,3,0),"")
A26: 22 | B26: 141 | C26: =VLOOKUP(B26,MASTER!$AC$16:$AD999,2,0) -> Stop Cock 15mm (M/T) | D26: =IFERROR(VLOOKUP(D$4&$B26,MASTER!$Z$16:$AB999,3,0),"") | E26: =IFERROR(VLOOKUP(E$4&$B26,MASTER!$Z$16:$AB999,3,0),"") | F26: =IFERROR(VLOOKUP(F$4&$B26,MASTER!$Z$16:$AB999,3,0),"") | G26: =IFERROR(VLOOKUP(G$4&$B26,MASTER!$Z$16:$AB999,3,0),"") | H26: =IFERROR(VLOOKUP(H$4&$B26,MASTER!$Z$16:$AB999,3,0),"") | I26: =IFERROR(VLOOKUP(I$4&$B26,MASTER!$Z$16:$AB999,3,0),"") | J26: =IFERROR(VLOOKUP(J$4&$B26,MASTER!$Z$16:$AB999,3,0),"") | K26: =IFERROR(VLOOKUP(K$4&$B26,MASTER!$Z$16:$AB999,3,0),"") | ... AC26: =IFERROR(VLOOKUP(AC$4&$B26,MASTER!$Z$16:$AB999,3,0),"")
A27: 23 | B27: 141-N | C27: =VLOOKUP(B27,MASTER!$AC$16:$AD999,2,0) -> Stop Cock 15mm with Nozzle | D27: =IFERROR(VLOOKUP(D$4&$B27,MASTER!$Z$16:$AB999,3,0),"") | E27: =IFERROR(VLOOKUP(E$4&$B27,MASTER!$Z$16:$AB999,3,0),"") | F27: =IFERROR(VLOOKUP(F$4&$B27,MASTER!$Z$16:$AB999,3,0),"") | G27: =IFERROR(VLOOKUP(G$4&$B27,MASTER!$Z$16:$AB999,3,0),"") | H27: =IFERROR(VLOOKUP(H$4&$B27,MASTER!$Z$16:$AB999,3,0),"") | I27: =IFERROR(VLOOKUP(I$4&$B27,MASTER!$Z$16:$AB999,3,0),"") | J27: =IFERROR(VLOOKUP(J$4&$B27,MASTER!$Z$16:$AB999,3,0),"") | K27: =IFERROR(VLOOKUP(K$4&$B27,MASTER!$Z$16:$AB999,3,0),"") | ... AC27: =IFERROR(VLOOKUP(AC$4&$B27,MASTER!$Z$16:$AB999,3,0),"")
A28: 24 | B28: 142 | C28: =VLOOKUP(B28,MASTER!$AC$16:$AD999,2,0) -> Stop Cock 15mm (F/T) | D28: =IFERROR(VLOOKUP(D$4&$B28,MASTER!$Z$16:$AB999,3,0),"") | E28: =IFERROR(VLOOKUP(E$4&$B28,MASTER!$Z$16:$AB999,3,0),"") | F28: =IFERROR(VLOOKUP(F$4&$B28,MASTER!$Z$16:$AB999,3,0),"") | G28: =IFERROR(VLOOKUP(G$4&$B28,MASTER!$Z$16:$AB999,3,0),"") | H28: =IFERROR(VLOOKUP(H$4&$B28,MASTER!$Z$16:$AB999,3,0),"") | I28: =IFERROR(VLOOKUP(I$4&$B28,MASTER!$Z$16:$AB999,3,0),"") | J28: =IFERROR(VLOOKUP(J$4&$B28,MASTER!$Z$16:$AB999,3,0),"") | K28: =IFERROR(VLOOKUP(K$4&$B28,MASTER!$Z$16:$AB999,3,0),"") | ... AC28: =IFERROR(VLOOKUP(AC$4&$B28,MASTER!$Z$16:$AB999,3,0),"")
A29: 25 | B29: 143 | C29: =VLOOKUP(B29,MASTER!$AC$16:$AD999,2,0) -> Stop Cock 20mm (F/T) | D29: =IFERROR(VLOOKUP(D$4&$B29,MASTER!$Z$16:$AB999,3,0),"") | E29: =IFERROR(VLOOKUP(E$4&$B29,MASTER!$Z$16:$AB999,3,0),"") | F29: =IFERROR(VLOOKUP(F$4&$B29,MASTER!$Z$16:$AB999,3,0),"") | G29: =IFERROR(VLOOKUP(G$4&$B29,MASTER!$Z$16:$AB999,3,0),"") | H29: =IFERROR(VLOOKUP(H$4&$B29,MASTER!$Z$16:$AB999,3,0),"") | I29: =IFERROR(VLOOKUP(I$4&$B29,MASTER!$Z$16:$AB999,3,0),"") | J29: =IFERROR(VLOOKUP(J$4&$B29,MASTER!$Z$16:$AB999,3,0),"") | K29: =IFERROR(VLOOKUP(K$4&$B29,MASTER!$Z$16:$AB999,3,0),"") | ... AC29: =IFERROR(VLOOKUP(AC$4&$B29,MASTER!$Z$16:$AB999,3,0),"")
A30: 26 | B30: 144 | C30: =VLOOKUP(B30,MASTER!$AC$16:$AD999,2,0) -> Angle Cock with Flange | D30: =IFERROR(VLOOKUP(D$4&$B30,MASTER!$Z$16:$AB999,3,0),"") -> 482 | E30: =IFERROR(VLOOKUP(E$4&$B30,MASTER!$Z$16:$AB999,3,0),"") -> 434 | F30: =IFERROR(VLOOKUP(F$4&$B30,MASTER!$Z$16:$AB999,3,0),"") -> 256 | G30: =IFERROR(VLOOKUP(G$4&$B30,MASTER!$Z$16:$AB999,3,0),"") -> 256 | H30: =IFERROR(VLOOKUP(H$4&$B30,MASTER!$Z$16:$AB999,3,0),"") -> 256 | I30: =IFERROR(VLOOKUP(I$4&$B30,MASTER!$Z$16:$AB999,3,0),"") -> 256 | J30: =IFERROR(VLOOKUP(J$4&$B30,MASTER!$Z$16:$AB999,3,0),"") -> 256 | K30: =IFERROR(VLOOKUP(K$4&$B30,MASTER!$Z$16:$AB999,3,0),"") -> 256 | ... AC30: =IFERROR(VLOOKUP(AC$4&$B30,MASTER!$Z$16:$AB999,3,0),"") -> 148
A31: 27 | B31: 145 | C31: =VLOOKUP(B31,MASTER!$AC$16:$AD999,2,0) -> 2 Way Angle Cock with Flange | D31: =IFERROR(VLOOKUP(D$4&$B31,MASTER!$Z$16:$AB999,3,0),"") -> 878 | E31: =IFERROR(VLOOKUP(E$4&$B31,MASTER!$Z$16:$AB999,3,0),"") -> 858 | F31: =IFERROR(VLOOKUP(F$4&$B31,MASTER!$Z$16:$AB999,3,0),"") -> 546 | G31: =IFERROR(VLOOKUP(G$4&$B31,MASTER!$Z$16:$AB999,3,0),"") -> 456 | H31: =IFERROR(VLOOKUP(H$4&$B31,MASTER!$Z$16:$AB999,3,0),"") -> 456 | I31: =IFERROR(VLOOKUP(I$4&$B31,MASTER!$Z$16:$AB999,3,0),"") -> 456 | J31: =IFERROR(VLOOKUP(J$4&$B31,MASTER!$Z$16:$AB999,3,0),"") -> 456 | K31: =IFERROR(VLOOKUP(K$4&$B31,MASTER!$Z$16:$AB999,3,0),"") -> 456 | ... AC31: =IFERROR(VLOOKUP(AC$4&$B31,MASTER!$Z$16:$AB999,3,0),"")
A32: 28 | B32: 146 | C32: =VLOOKUP(B32,MASTER!$AC$16:$AD999,2,0) -> Concealed Stop Cock 15mm | D32: =IFERROR(VLOOKUP(D$4&$B32,MASTER!$Z$16:$AB999,3,0),"") | E32: =IFERROR(VLOOKUP(E$4&$B32,MASTER!$Z$16:$AB999,3,0),"") | F32: =IFERROR(VLOOKUP(F$4&$B32,MASTER!$Z$16:$AB999,3,0),"") | G32: =IFERROR(VLOOKUP(G$4&$B32,MASTER!$Z$16:$AB999,3,0),"") | H32: =IFERROR(VLOOKUP(H$4&$B32,MASTER!$Z$16:$AB999,3,0),"") | I32: =IFERROR(VLOOKUP(I$4&$B32,MASTER!$Z$16:$AB999,3,0),"") | J32: =IFERROR(VLOOKUP(J$4&$B32,MASTER!$Z$16:$AB999,3,0),"") | K32: =IFERROR(VLOOKUP(K$4&$B32,MASTER!$Z$16:$AB999,3,0),"") | ... AC32: =IFERROR(VLOOKUP(AC$4&$B32,MASTER!$Z$16:$AB999,3,0),"")
A33: 29 | B33: 148 | C33: =VLOOKUP(B33,MASTER!$AC$16:$AD999,2,0) -> Concealed Stop Cock 20mm | D33: =IFERROR(VLOOKUP(D$4&$B33,MASTER!$Z$16:$AB999,3,0),"") | E33: =IFERROR(VLOOKUP(E$4&$B33,MASTER!$Z$16:$AB999,3,0),"") | F33: =IFERROR(VLOOKUP(F$4&$B33,MASTER!$Z$16:$AB999,3,0),"") | G33: =IFERROR(VLOOKUP(G$4&$B33,MASTER!$Z$16:$AB999,3,0),"") | H33: =IFERROR(VLOOKUP(H$4&$B33,MASTER!$Z$16:$AB999,3,0),"") | I33: =IFERROR(VLOOKUP(I$4&$B33,MASTER!$Z$16:$AB999,3,0),"") | J33: =IFERROR(VLOOKUP(J$4&$B33,MASTER!$Z$16:$AB999,3,0),"") | K33: =IFERROR(VLOOKUP(K$4&$B33,MASTER!$Z$16:$AB999,3,0),"") | ... AC33: =IFERROR(VLOOKUP(AC$4&$B33,MASTER!$Z$16:$AB999,3,0),"")
A34: 30 | B34: 146-B | C34: =VLOOKUP(B34,MASTER!$AC$16:$AD999,2,0) -> Concealed Stop Cock 15mm with Brass Body | D34: =IFERROR(VLOOKUP(D$4&$B34,MASTER!$Z$16:$AB999,3,0),"") -> 1672 | E34: =IFERROR(VLOOKUP(E$4&$B34,MASTER!$Z$16:$AB999,3,0),"") | F34: =IFERROR(VLOOKUP(F$4&$B34,MASTER!$Z$16:$AB999,3,0),"") | G34: =IFERROR(VLOOKUP(G$4&$B34,MASTER!$Z$16:$AB999,3,0),"") | H34: =IFERROR(VLOOKUP(H$4&$B34,MASTER!$Z$16:$AB999,3,0),"") | I34: =IFERROR(VLOOKUP(I$4&$B34,MASTER!$Z$16:$AB999,3,0),"") | J34: =IFERROR(VLOOKUP(J$4&$B34,MASTER!$Z$16:$AB999,3,0),"") | K34: =IFERROR(VLOOKUP(K$4&$B34,MASTER!$Z$16:$AB999,3,0),"") | ... AC34: =IFERROR(VLOOKUP(AC$4&$B34,MASTER!$Z$16:$AB999,3,0),"")
A35: 31 | B35: 148-B | C35: =VLOOKUP(B35,MASTER!$AC$16:$AD999,2,0) -> Concealed Stop Cock 20mm with Brass Body | D35: =IFERROR(VLOOKUP(D$4&$B35,MASTER!$Z$16:$AB999,3,0),"") -> 1698 | E35: =IFERROR(VLOOKUP(E$4&$B35,MASTER!$Z$16:$AB999,3,0),"") | F35: =IFERROR(VLOOKUP(F$4&$B35,MASTER!$Z$16:$AB999,3,0),"") | G35: =IFERROR(VLOOKUP(G$4&$B35,MASTER!$Z$16:$AB999,3,0),"") | H35: =IFERROR(VLOOKUP(H$4&$B35,MASTER!$Z$16:$AB999,3,0),"") | I35: =IFERROR(VLOOKUP(I$4&$B35,MASTER!$Z$16:$AB999,3,0),"") | J35: =IFERROR(VLOOKUP(J$4&$B35,MASTER!$Z$16:$AB999,3,0),"") | K35: =IFERROR(VLOOKUP(K$4&$B35,MASTER!$Z$16:$AB999,3,0),"") | ... AC35: =IFERROR(VLOOKUP(AC$4&$B35,MASTER!$Z$16:$AB999,3,0),"")
A36: 32 | B36: 147 | C36: =VLOOKUP(B36,MASTER!$AC$16:$AD999,2,0) -> Pillar Cock Swan Neck (T/M) with Flange | D36: =IFERROR(VLOOKUP(D$4&$B36,MASTER!$Z$16:$AB999,3,0),"") -> 858 | E36: =IFERROR(VLOOKUP(E$4&$B36,MASTER!$Z$16:$AB999,3,0),"") -> 848 | F36: =IFERROR(VLOOKUP(F$4&$B36,MASTER!$Z$16:$AB999,3,0),"") -> 658 | G36: =IFERROR(VLOOKUP(G$4&$B36,MASTER!$Z$16:$AB999,3,0),"") -> 642 | H36: =IFERROR(VLOOKUP(H$4&$B36,MASTER!$Z$16:$AB999,3,0),"") -> 642 | I36: =IFERROR(VLOOKUP(I$4&$B36,MASTER!$Z$16:$AB999,3,0),"") -> 642 | J36: =IFERROR(VLOOKUP(J$4&$B36,MASTER!$Z$16:$AB999,3,0),"") -> 642 | K36: =IFERROR(VLOOKUP(K$4&$B36,MASTER!$Z$16:$AB999,3,0),"") -> 642 | ... AC36: =IFERROR(VLOOKUP(AC$4&$B36,MASTER!$Z$16:$AB999,3,0),"")
A37: 33 | B37: 147-Q | C37: =VLOOKUP(B37,MASTER!$AC$16:$AD999,2,0) -> Pillar Cock Swan Neck (T/M) Square Spout with Flange | D37: =IFERROR(VLOOKUP(D$4&$B37,MASTER!$Z$16:$AB999,3,0),"") | E37: =IFERROR(VLOOKUP(E$4&$B37,MASTER!$Z$16:$AB999,3,0),"") -> 1024 | F37: =IFERROR(VLOOKUP(F$4&$B37,MASTER!$Z$16:$AB999,3,0),"") | G37: =IFERROR(VLOOKUP(G$4&$B37,MASTER!$Z$16:$AB999,3,0),"") | H37: =IFERROR(VLOOKUP(H$4&$B37,MASTER!$Z$16:$AB999,3,0),"") | I37: =IFERROR(VLOOKUP(I$4&$B37,MASTER!$Z$16:$AB999,3,0),"") | J37: =IFERROR(VLOOKUP(J$4&$B37,MASTER!$Z$16:$AB999,3,0),"") | K37: =IFERROR(VLOOKUP(K$4&$B37,MASTER!$Z$16:$AB999,3,0),"") | ... AC37: =IFERROR(VLOOKUP(AC$4&$B37,MASTER!$Z$16:$AB999,3,0),"")
A38: 34 | B38: 149 | C38: =VLOOKUP(B38,MASTER!$AC$16:$AD999,2,0) -> Washing Machine Tap with Flange | D38: =IFERROR(VLOOKUP(D$4&$B38,MASTER!$Z$16:$AB999,3,0),"") | E38: =IFERROR(VLOOKUP(E$4&$B38,MASTER!$Z$16:$AB999,3,0),"") | F38: =IFERROR(VLOOKUP(F$4&$B38,MASTER!$Z$16:$AB999,3,0),"") -> 424 | G38: =IFERROR(VLOOKUP(G$4&$B38,MASTER!$Z$16:$AB999,3,0),"") -> 392 | H38: =IFERROR(VLOOKUP(H$4&$B38,MASTER!$Z$16:$AB999,3,0),"") -> 392 | I38: =IFERROR(VLOOKUP(I$4&$B38,MASTER!$Z$16:$AB999,3,0),"") -> 392 | J38: =IFERROR(VLOOKUP(J$4&$B38,MASTER!$Z$16:$AB999,3,0),"") -> 392 | K38: =IFERROR(VLOOKUP(K$4&$B38,MASTER!$Z$16:$AB999,3,0),"") -> 392 | ... AC38: =IFERROR(VLOOKUP(AC$4&$B38,MASTER!$Z$16:$AB999,3,0),"")
A39: 35 | B39: 150 | C39: =VLOOKUP(B39,MASTER!$AC$16:$AD999,2,0) -> Center Hole Basin Mixer | D39: =IFERROR(VLOOKUP(D$4&$B39,MASTER!$Z$16:$AB999,3,0),"") -> 2446 | E39: =IFERROR(VLOOKUP(E$4&$B39,MASTER!$Z$16:$AB999,3,0),"") -> 2028 | F39: =IFERROR(VLOOKUP(F$4&$B39,MASTER!$Z$16:$AB999,3,0),"") | G39: =IFERROR(VLOOKUP(G$4&$B39,MASTER!$Z$16:$AB999,3,0),"") | H39: =IFERROR(VLOOKUP(H$4&$B39,MASTER!$Z$16:$AB999,3,0),"") | I39: =IFERROR(VLOOKUP(I$4&$B39,MASTER!$Z$16:$AB999,3,0),"") | J39: =IFERROR(VLOOKUP(J$4&$B39,MASTER!$Z$16:$AB999,3,0),"") | K39: =IFERROR(VLOOKUP(K$4&$B39,MASTER!$Z$16:$AB999,3,0),"") | ... AC39: =IFERROR(VLOOKUP(AC$4&$B39,MASTER!$Z$16:$AB999,3,0),"")
A40: 36 | B40: 400 | C40: =VLOOKUP(B40,MASTER!$AC$16:$AD999,2,0) -> Single Lever Basin Mixer | D40: =IFERROR(VLOOKUP(D$4&$B40,MASTER!$Z$16:$AB999,3,0),"") | E40: =IFERROR(VLOOKUP(E$4&$B40,MASTER!$Z$16:$AB999,3,0),"") -> 2382 | F40: =IFERROR(VLOOKUP(F$4&$B40,MASTER!$Z$16:$AB999,3,0),"") | G40: =IFERROR(VLOOKUP(G$4&$B40,MASTER!$Z$16:$AB999,3,0),"") | H40: =IFERROR(VLOOKUP(H$4&$B40,MASTER!$Z$16:$AB999,3,0),"") | I40: =IFERROR(VLOOKUP(I$4&$B40,MASTER!$Z$16:$AB999,3,0),"") | J40: =IFERROR(VLOOKUP(J$4&$B40,MASTER!$Z$16:$AB999,3,0),"") | K40: =IFERROR(VLOOKUP(K$4&$B40,MASTER!$Z$16:$AB999,3,0),"") | ... AC40: =IFERROR(VLOOKUP(AC$4&$B40,MASTER!$Z$16:$AB999,3,0),"")

Sheet Allied
A1: 4%+2%
B2: Range | C2: Code | D2: SUPERIOR BODY CONCEALED STOP COCK WITH FITTING | E2: 5th Mar, 2026 | F2: 01st Sep, 2026 | G2: Diff. in %age | H2: 01st May, 2026 | I2: Diff. in %age
B3: CNS-15 | D3: Concealed Stop Cock Suitable For 15mm Pipe Line with 1/2" Spindle | E3: 860 | F3: 1020 | G3: =IFERROR(DIVIDE(MINUS(F3,E3),E3),) -> 0.18604651 | H3: 940 | I3: =IFERROR(DIVIDE(MINUS(F3,H3),H3),) -> 0.085106383
B4: CNS-20 | D4: Concealed Stop Cock Suitable For 20mm Pipe Line with 1/2" Spindle | E4: 900 | F4: 1060 | G4: =IFERROR(DIVIDE(MINUS(F4,E4),E4),) -> 0.17777778 | H4: 980 | I4: =IFERROR(DIVIDE(MINUS(F4,H4),H4),) -> 0.081632653
B6: Quadra | C6: PQ-18 | D6: Concealed Stop Cock (Handle, Sleeve & Flange Only) | E6: 330 | F6: 360 | G6: =IFERROR(DIVIDE(MINUS(F6,E6),E6),) -> 0.090909091
C7: 146-Q | D7: Concealed Stop Cock Spindle 15mm & Body 15mm | E7: 1190 | F7: 1290 | G7: =IFERROR(DIVIDE(MINUS(F7,E7),E7),) -> 0.084033613
C8: 148-Q | D8: Concealed Stop Cock Spindle 20mm & Body 20mm | E8: 1230 | F8: 1330 | G8: =IFERROR(DIVIDE(MINUS(F8,E8),E8),) -> 0.081300813
B10: Delta | C10: PD-18 | D10: Concealed Stop Cock (Handle, Sleeve & Flange Only) | E10: 330 | F10: 360 | G10: =IFERROR(DIVIDE(MINUS(F10,E10),E10),) -> 0.090909091
C11: 146-D | D11: Concealed Stop Cock Spindle 15mm & Body 15mm | E11: 1190 | F11: 1290 | G11: =IFERROR(DIVIDE(MINUS(F11,E11),E11),) -> 0.084033613
C12: 148-D | D12: Concealed Stop Cock Spindle 20mm & Body 20mm | E12: 1230 | F12: 1330 | G12: =IFERROR(DIVIDE(MINUS(F12,E12),E12),) -> 0.081300813
B14: Ibix | C14: PI-18 | D14: Concealed Stop Cock (Handle, Sleeve & Flange Only) | E14: 330 | F14: 360 | G14: =IFERROR(DIVIDE(MINUS(F14,E14),E14),) -> 0.090909091
C15: 146-I | D15: Concealed Stop Cock Spindle 15mm & Body 15mm | E15: 1190 | F15: 1290 | G15: =IFERROR(DIVIDE(MINUS(F15,E15),E15),) -> 0.084033613
C16: 148-I | D16: Concealed Stop Cock Spindle 20mm & Body 20mm | E16: 1230 | F16: 1330 | G16: =IFERROR(DIVIDE(MINUS(F16,E16),E16),) -> 0.081300813
B18: Ovian | C18: PR-18 | D18: Concealed Stop Cock (Handle, Sleeve & Flange Only) | E18: 330 | F18: 360 | G18: =IFERROR(DIVIDE(MINUS(F18,E18),E18),) -> 0.090909091
C19: 146-R | D19: Concealed Stop Cock Spindle 15mm & Body 15mm | E19: 1190 | F19: 1290 | G19: =IFERROR(DIVIDE(MINUS(F19,E19),E19),) -> 0.084033613
C20: 148-R | D20: Concealed Stop Cock Spindle 20mm & Body 20mm | E20: 1230 | F20: 1330 | G20: =IFERROR(DIVIDE(MINUS(F20,E20),E20),) -> 0.081300813
B22: STANDARD (Old Handle) | C22: 146-BO | D22: Concealed Stop Cock 15mm with Brass Body | E22: 1256 | F22: 1398 | G22: =IFERROR(DIVIDE(MINUS(F22,E22),E22),) -> 0.11305732
C23: 148-BO | D23: Concealed Stop Cock 20mm with Brass Body | E23: 1276 | F23: 1428 | G23: =IFERROR(DIVIDE(MINUS(F23,E23),E23),) -> 0.11912226
B24: STANDARD | C24: 146-B | D24: Concealed Stop Cock 15mm with Brass Body | E24: 1256 | F24: 1398 | G24: =IFERROR(DIVIDE(MINUS(F24,E24),E24),) -> 0.11305732
C25: 148-B | D25: Concealed Stop Cock 20mm with Brass Body | E25: 1276 | F25: 1428 | G25: =IFERROR(DIVIDE(MINUS(F25,E25),E25),) -> 0.11912226
B26: Helix | C26: 146-HB | D26: Concealed Stop Cock 15mm with Brass Body | E26: 1236 | F26: 1384 | G26: =IFERROR(DIVIDE(MINUS(F26,E26),E26),) -> 0.1197411
C27: 148-HB | D27: Concealed Stop Cock 20mm with Brass Body | E27: 1248 | F27: 1398 | G27: =IFERROR(DIVIDE(MINUS(F27,E27),E27),) -> 0.12019231
B28: Delta | C28: 146-DB | D28: Concealed Stop Cock 15mm with Brass Body | E28: 1548 | F28: 1734 | G28: =IFERROR(DIVIDE(MINUS(F28,E28),E28),) -> 0.12015504
C29: 148-DB | D29: Concealed Stop Cock 20mm with Brass Body | E29: 1576 | F29: 1766 | G29: =IFERROR(DIVIDE(MINUS(F29,E29),E29),) -> 0.12055838
B30: Quadra | C30: 146-QB | D30: Concealed Stop Cock 15mm with Brass Body | E30: 1318 | F30: 1476 | G30: =IFERROR(DIVIDE(MINUS(F30,E30),E30),) -> 0.1198786
C31: 148-QB | D31: Concealed Stop Cock 20mm with Brass Body | E31: 1346 | F31: 1498 | G31: =IFERROR(DIVIDE(MINUS(F31,E31),E31),) -> 0.11292719
B32: Ovian | C32: 146-RB | D32: Concealed Stop Cock 15mm with Brass Body | E32: 1328 | F32: 1486 | G32: =IFERROR(DIVIDE(MINUS(F32,E32),E32),) -> 0.1189759
C33: 148-RB | D33: Concealed Stop Cock 20mm with Brass Body | E33: 1346 | F33: 1498 | G33: =IFERROR(DIVIDE(MINUS(F33,E33),E33),) -> 0.11292719

Sheet NEW PTMT
B2: Cat No. | C2: Name | D2: 5th Mar, 2026 | E2: 01st Sep, 2026 | G2: Diff. in %age | I2: COUPON | J2: Master Box | K2: Master Box Packing
B3: Novo Series
A4: 1 | B4: 123-NN | C4: Bib Cock Fancy 15mm (Foam Flow) with Flange | D4: 298 | E4: 322 | G4: =IFERROR(DIVIDE(MINUS(E4,D4),D4),) -> 0.080536913 | I4: 2.88 | J4: {=IFERROR(VLOOKUP(B4:B1878,PACKING!$A$3:$D1878,{3,4},0),"")} -> 54 | K4: 216
A5: 2 | B5: 124-N | C5: Bib Cock Long Body 15mm (Foam Flow) with Flange | D5: 362 | E5: 392 | G5: =IFERROR(DIVIDE(MINUS(E5,D5),D5),) -> 0.082872928 | I5: 3.4 | J5: 33 | K5: 132
A6: 3 | B6: 127-N | C6: Bib Cock Nozzle with Flange | D6: 332 | E6: 358 | G6: =IFERROR(DIVIDE(MINUS(E6,D6),D6),) -> 0.078313253 | I6: 3.1 | J6: 33 | K6: 132
A7: 4 | B7: 129-N | C7: 2 Way Bib Cock Foam Flow with Flange | D7: 572 | E7: 618 | G7: =IFERROR(DIVIDE(MINUS(E7,D7),D7),) -> 0.08041958 | I7: 5.38 | J7: 28 | K7: 112
A8: 5 | B8: 130-N | C8: Pillar Cock Foam Flow with Flange | D8: 432 | E8: 468 | G8: =IFERROR(DIVIDE(MINUS(E8,D8),D8),) -> 0.083333333 | I8: 4.06 | J8: 30 | K8: 120
A9: 6 | B9: 132-N | C9: Sink Cock (W/M) Foam Flow with Flange | D9: 658 | E9: 712 | G9: =IFERROR(DIVIDE(MINUS(E9,D9),D9),) -> 0.082066869 | I9: 6.18 | J9: 13 | K9: 52
A10: 7 | B10: 1322-N | C10: Sink Cock Swan Neck (W/M) Small Spout Foam Flow with Flange | D10: 632 | E10: 684 | G10: =IFERROR(DIVIDE(MINUS(E10,D10),D10),) -> 0.082278481 | I10: 5.94 | J10: 30 | K10: 120
A11: 8 | B11: 133-N | C11: Sink Cock Swan Neck (T/M) Long Spout Foam Flow with Flange | D11: 698.0064 | E11: 754 | G11: =IFERROR(DIVIDE(MINUS(E11,D11),D11),) -> 0.080219322 | I11: 6 | J11: 13 | K11: 52
A12: 9 | B12: 134-N | C12: Sink Mixer Foam Flow with Flange | D12: 1572 | E12: 1698 | G12: =IFERROR(DIVIDE(MINUS(E12,D12),D12),) -> 0.080152672 | I12: 14.8 | J12: 13 | K12: 52
A13: 10 | B13: 135-N | C13: Wall Mixer Foam Flow with Flange | D13: 1527.552 | E13: 1648 | G13: =IFERROR(DIVIDE(MINUS(E13,D13),D13),) -> 0.078850344 | I13: 15 | J13: 13 | K13: 52
B14: 1374-N | C14: 2 in 1 Telephonic Wall Mixer with Crutch & Hand Shower with 1.5 Mtr Tube | D14: 2092 | E14: 2258 | G14: =IFERROR(DIVIDE(MINUS(E14,D14),D14),) -> 0.079349904
A15: 11 | B15: 1375-N | C15: Wall Mixer L Bend Foam Flow with Flange | D15: 1784 | E15: 1928 | G15: =IFERROR(DIVIDE(MINUS(E15,D15),D15),) -> 0.080717489 | I15: 15 | J15: 6 | K15: 24
A16: 12 | B16: 144-N | C16: Angle Cock with Flange | D16: 272 | E16: 294 | G16: =IFERROR(DIVIDE(MINUS(E16,D16),D16),) -> 0.080882353 | I16: 2 | J16: 66 | K16: 198
A17: 13 | B17: 145-N | C17: 2 Way Angle Cock Foam Flow with Flange | D17: 507.96 | E17: 548 | G17: =IFERROR(DIVIDE(MINUS(E17,D17),D17),) -> 0.078825104 | I17: 4.8 | J17: 35 | K17: 140
B18: 147-N | C18: Pillar Cock Swan Neck Square Spout Foam Flow with Flange | D18: 711.96 | E18: 768 | G18: =IFERROR(DIVIDE(MINUS(E18,D18),D18),) -> 0.078712287 | I18: 6 | J18: 30 | K18: 120
B20: Ultra Series
A21: 1 | B21: 123-U | C21: Bib Cock Fancy 15mm (Foam Flow) with Flange | D21: 395.76 | E21: 426 | G21: =IFERROR(DIVIDE(MINUS(E21,D21),D21),) -> 0.076409945 | I21: 3.76 | J21: 33 | K21: 132
A22: 2 | B22: 124-U | C22: Bib Cock Long Body 15mm (Foam Flow) with Flange | D22: 485.8464 | E22: 526 | G22: =IFERROR(DIVIDE(MINUS(E22,D22),D22),) -> 0.082646697 | I22: 4.58 | J22: 33 | K22: 99
A23: 3 | B23: 127-U | C23: Bib Cock Nozzle with Flange | D23: 422.1984 | E23: 456 | G23: =IFERROR(DIVIDE(MINUS(E23,D23),D23),) -> 0.080060938 | I23: 3.98 | J23: 33 | K23: 132
A24: 4 | B24: 129-U | C24: 2 Way Bib Cock (Foam Flow) with Flange | D24: 732 | E24: 792 | G24: =IFERROR(DIVIDE(MINUS(E24,D24),D24),) -> 0.081967213 | I24: 6 | J24: 24 | K24: 48
A25: 5 | B25: 130-U | C25: Pillar Cock (Foam Flow) with Flange | D25: 497.76 | E25: 538 | G25: =IFERROR(DIVIDE(MINUS(E25,D25),D25),) -> 0.080842173 | I25: 4.7 | J25: 30 | K25: 90
A26: 6 | B26: 132-U | C26: Sink Cock (W/M) (Foam Flow) with Flange | D26: 784 | E26: 848 | G26: =IFERROR(DIVIDE(MINUS(E26,D26),D26),) -> 0.081632653 | I26: 6 | J26: 13 | K26: 52
B27: 1322-U | C27: Sink Cock Swan Neck (W/M) Small Spout Foam Flow with Flange | D27: 738.3168 | E27: 798 | G27: =IFERROR(DIVIDE(MINUS(E27,D27),D27),) -> 0.080836844 | I27: 6 | J27: 30 | K27: 120
A28: 7 | B28: 133-U | C28: Sink Cock Swan Neck (T/M) Long Spout Foam Flow with Flange | D28: 784 | E28: 848 | G28: =IFERROR(DIVIDE(MINUS(E28,D28),D28),) -> 0.081632653 | I28: 6 | J28: 13 | K28: 52
A29: 8 | B29: 134-U | C29: Sink Mixer Foam Flow with Flange | D29: 1632 | E29: 1764 | G29: =IFERROR(DIVIDE(MINUS(E29,D29),D29),) -> 0.080882353 | I29: 15.4 | J29: 13 | K29: 52
A30: 9 | B30: 135-U | C30: Wall Mixer Foam Flow with Flange | D30: 1572 | E30: 1698 | G30: =IFERROR(DIVIDE(MINUS(E30,D30),D30),) -> 0.080152672 | I30: 14.6 | J30: 13 | K30: 52
B31: 1374-U | C31: 2 in 1 Telephonic Wall Mixer with Crutch & Hand Shower with 1.5 Mtr Tube | D31: 2286 | E31: 2468 | G31: =IFERROR(DIVIDE(MINUS(E31,D31),D31),) -> 0.079615048
A32: 10 | B32: 1375-U | C32: Wall Mixer (Foam Flow) with L Bend | D32: 1982 | E32: 2138 | G32: =IFERROR(DIVIDE(MINUS(E32,D32),D32),) -> 0.078708375 | I32: 14.6 | J32: 6 | K32: 24
A33: 11 | B33: 144-U | C33: Angle Cock with Flange | D33: 352 | E33: 378 | G33: =IFERROR(DIVIDE(MINUS(E33,D33),D33),) -> 0.073863636 | I33: 2 | J33: 66 | K33: 198
A34: 12 | B34: 145-U | C34: 2 Way Angle Cock with Flange | D34: 682 | E34: 738 | G34: =IFERROR(DIVIDE(MINUS(E34,D34),D34),) -> 0.082111437 | I34: 6.44 | J34: 23 | K34: 92
A35: 13 | B35: 147-U | C35: Pillar Cock Swan Neck Foam Flow with Flange | D35: 682 | E35: 738 | G35: =IFERROR(DIVIDE(MINUS(E35,D35),D35),) -> 0.082111437 | I35: 6.4 | J35: 30 | K35: 90
A36: 14 | B36: 150-U | C36: Center Hole Basin Mixer Foam Flow | D36: 1776 | E36: 1918 | G36: =IFERROR(DIVIDE(MINUS(E36,D36),D36),) -> 0.079954955 | I36: 15 | J36: 14 | K36: 56
G37: =IFERROR(DIVIDE(MINUS(E37,D37),D37),)
B38: Quadra Series | G38: =IFERROR(DIVIDE(MINUS(E38,D38),D38),)
A39: 1 | B39: 123-Q | C39: Bib Cock Fancy 15mm Foam Flow with Flange | D39: 375.5232 | E39: 406 | G39: =IFERROR(DIVIDE(MINUS(E39,D39),D39),) -> 0.081158235 | I39: 3.54 | J39: 33 | K39: 132
A40: 2 | B40: 124-Q | C40: Bib Cock Long Body 15mm (Foam Flow) with Flange | D40: 472 | E40: 508 | G40: =IFERROR(DIVIDE(MINUS(E40,D40),D40),) -> 0.076271186 | I40: 4.44 | J40: 33 | K40: 99
A41: 3 | B41: 127-Q | C41: Bib Cock Nozzle with Flange | D41: 402 | E41: 434 | G41: =IFERROR(DIVIDE(MINUS(E41,D41),D41),) -> 0.07960199 | I41: 3.78 | J41: 33 | K41: 99
A42: 4 | B42: 129-Q | C42: 2 Way Bib Cock Foam Flow with Flange | D42: 707.88 | E42: 766 | G42: =IFERROR(DIVIDE(MINUS(E42,D42),D42),) -> 0.082104311 | I42: 6 | J42: 24 | K42: 48
...

Sheet NEW ITEMS
A1: 0.02
B2: Cat No. | C2: Name | D2: NEW | E2: 46086
B3: Novo Series
B4: 1374-N | C4: 2 in 1 Telephonic Wall Mixer with Crutch (Hand Shower with 1.5 Mtr Tube) | D4: NEW | E4: 2092
B6: Novo Royal Series
B7: 1374-NR | C7: 2 in 1 Telephonic Wall Mixer with Crutch (Hand Shower with 1.5 Mtr Tube) | D7: NEW | E7: 2217.52
B9: Novo Peach Series
B10: 1374-NP | C10: 2 in 1 Telephonic Wall Mixer with Crutch (Hand Shower with 1.5 Mtr Tube) | D10: NEW | E10: 2217.52
B12: Novo Gold Series
B13: 1374-NG | C13: 2 in 1 Telephonic Wall Mixer with Crutch (Hand Shower with 1.5 Mtr Tube) | D13: NEW | E13: 2217.52
B15: Novo Wine Series
B16: 1374-NW | C16: 2 in 1 Telephonic Wall Mixer with Crutch (Hand Shower with 1.5 Mtr Tube) | D16: NEW | E16: 2217.52
B18: Novo Black Series
B19: 1374-NBB | C19: 2 in 1 Telephonic Wall Mixer with Crutch (Hand Shower with 1.5 Mtr Tube) | D19: NEW | E19: 2217.52
B21: Novo Dark Blue Series
B22: 1374-NB | C22: 2 in 1 Telephonic Wall Mixer with Crutch (Hand Shower with 1.5 Mtr Tube) | D22: NEW | E22: 2217.52
B24: Ultra Series
B25: 1374-U | C25: 2 in 1 Telephonic Wall Mixer with Crutch (Hand Shower with 1.5 Mtr Tube) | D25: NEW | E25: 2286
B27: Ultra Wine Series
B28: 1374-UW | C28: 2 in 1 Telephonic Wall Mixer with Crutch (Hand Shower with 1.5 Mtr Tube) | D28: NEW | E28: 2424
B30: Ultra Gold Series
B31: 1374-UG | C31: 2 in 1 Telephonic Wall Mixer with Crutch (Hand Shower with 1.5 Mtr Tube) | D31: NEW | E31: 2424
B33: Ultra Royal Series
B34: 1374-UR | C34: 2 in 1 Telephonic Wall Mixer with Crutch (Hand Shower with 1.5 Mtr Tube) | D34: NEW | E34: 2424
B36: Ultra Peach Series
B37: 1374-UP | C37: 2 in 1 Telephonic Wall Mixer with Crutch (Hand Shower with 1.5 Mtr Tube) | D37: NEW | E37: 2424
B39: Ultra Black Series
B40: 1374-UB | C40: 2 in 1 Telephonic Wall Mixer with Crutch (Hand Shower with 1.5 Mtr Tube) | D40: NEW | E40: 2424
B42: Quadra Series
B43: 131-Q | C43: Pillar Cock 12" Tall Height with Flange | D43: NEW | E43: 756
B44: 1374-Q | C44: 2 in 1 Telephonic Wall Mixer with Crutch (Hand Shower with 1.5 Mtr Tube) | D44: NEW | E44: 2233.8
B46: Quadra Royal Series
B47: 131-QR | C47: Pillar Cock 12" Tall Height with Flange | D47: NEW | E47: 798
B48: 1374-QR | C48: 2 in 1 Telephonic Wall Mixer with Crutch (Hand Shower with 1.5 Mtr Tube) | D48: NEW | E48: 2367.828
B50: Quadra Peach Series
B51: 131-QP | C51: Pillar Cock 12" Tall Height with Flange | D51: NEW | E51: 798
B52: 1374-QP | C52: 2 in 1 Telephonic Wall Mixer with Crutch (Hand Shower with 1.5 Mtr Tube) | D52: NEW | E52: 2367.828
B54: Quadra Gold Series
B55: 131-QG | C55: Pillar Cock 12" Tall Height with Flange | D55: NEW | E55: 798
B56: 1374-QG | C56: 2 in 1 Telephonic Wall Mixer with Crutch (Hand Shower with 1.5 Mtr Tube) | D56: NEW | E56: 2367.828
...

Sheet COLOUR WISE
B2: Cat No. | C2: Name | D2: 5th Mar, 2026 | E2: 01st Sep, 2026 | G2: Diff. in %age | H2: 1.06 | I2: Master Box | J2: Master Box Packing
B3: Novo Royal Series
B4: 123-NNR | C4: Bib Cock (Foam Flow) with Flange | D4: 315.88 | E4: 342 | F4: =H4*$H$2 -> 341.32 | G4: =IFERROR(DIVIDE(MINUS(E4,D4),D4),) -> 0.082689629 | H4: =VLOOKUP(M4,'NEW PTMT'!$B$4:$E1406,4,0) -> 322 | I4: {=IFERROR(VLOOKUP(B4:B1406,PACKING!$A$3:$D1406,{3,4},0),"")} -> 54 | J4: 216 | M4: 123-NN
B5: 124-NR | C5: Long Body Bib Cock (Foam Flow) with Flange | D5: 383.72 | E5: 416 | F5: =H5*$H$2 -> 415.52 | G5: =IFERROR(DIVIDE(MINUS(E5,D5),D5),) -> 0.08412384 | H5: =VLOOKUP(M5,'NEW PTMT'!$B$4:$E1406,4,0) -> 392 | I5: 33 | J5: 132 | M5: 124-N
B6: 127-NR | C6: Bib Cock Nozzle with Flange | D6: 351.92 | E6: 378 | F6: =H6*$H$2 -> 379.48 | G6: =IFERROR(DIVIDE(MINUS(E6,D6),D6),) -> 0.074107752 | H6: =VLOOKUP(M6,'NEW PTMT'!$B$4:$E1406,4,0) -> 358 | I6: 33 | J6: 132 | M6: 127-N
B7: 129-NR | C7: 2 Way Bib Cock (Foam Flow) with Flange | D7: 606.32 | E7: 654 | F7: =H7*$H$2 -> 655.08 | G7: =IFERROR(DIVIDE(MINUS(E7,D7),D7),) -> 0.078638343 | H7: =VLOOKUP(M7,'NEW PTMT'!$B$4:$E1406,4,0) -> 618 | I7: 28 | J7: 112 | M7: 129-N
B8: 130-NR | C8: Pillar Cock (Foam Flow) with Flange | D8: 457.92 | E8: 496 | F8: =H8*$H$2 -> 496.08 | G8: =IFERROR(DIVIDE(MINUS(E8,D8),D8),) -> 0.08315863 | H8: =VLOOKUP(M8,'NEW PTMT'!$B$4:$E1406,4,0) -> 468 | I8: 30 | J8: 120 | M8: 130-N
B9: 132-NR | C9: Sink Cock (W/M) (Foam Flow) with Flange | D9: 698 | E9: 754 | F9: =H9*$H$2 -> 754.72 | G9: =IFERROR(DIVIDE(MINUS(E9,D9),D9),) -> 0.080229226 | H9: =VLOOKUP(M9,'NEW PTMT'!$B$4:$E1406,4,0) -> 712 | I9: 13 | J9: 52 | M9: 132-N
B10: 1322-NR | C10: Sink Cock Swan Neck Small Spout (Foam Flow) With Flange | D10: 669.92 | E10: 724 | F10: =H10*$H$2 -> 725.04 | G10: =IFERROR(DIVIDE(MINUS(E10,D10),D10),) -> 0.080726057 | H10: =VLOOKUP(M10,'NEW PTMT'!$B$4:$E1406,4,0) -> 684 | I10: 30 | J10: 120 | M10: 1322-N
B11: 133-NR | C11: Sink Cock Swan Neck (T/M) Square Spout (Foam Flow) with Flange | D11: 739.88678 | E11: 798 | F11: =H11*$H$2 -> 799.24 | G11: =IFERROR(DIVIDE(MINUS(E11,D11),D11),) -> 0.07854339 | H11: =VLOOKUP(M11,'NEW PTMT'!$B$4:$E1406,4,0) -> 754 | I11: 13 | J11: 52 | M11: 133-N
B12: 134-NR | C12: Sink Mixer (Foam Flow) with Flange | D12: 1666.32 | E12: 1798 | F12: =H12*$H$2 -> 1799.88 | G12: =IFERROR(DIVIDE(MINUS(E12,D12),D12),) -> 0.079024437 | H12: =VLOOKUP(M12,'NEW PTMT'!$B$4:$E1406,4,0) -> 1698 | I12: 13 | J12: 52 | M12: 134-N
B13: 135-NR | C13: Wall Mixer (Foam Flow) with Flange | D13: 1620 | E13: 1748 | F13: =H13*$H$2 -> 1746.88 | G13: =IFERROR(DIVIDE(MINUS(E13,D13),D13),) -> 0.079012346 | H13: =VLOOKUP(M13,'NEW PTMT'!$B$4:$E1406,4,0) -> 1648 | I13: 13 | J13: 52 | M13: 135-N
B14: 1374-NR | C14: 2 in 1 Telephonic Wall Mixer with Crutch & Hand Shower with 1.5 Mtr Tube | D14: 2217.52 | E14: 2394 | F14: =H14*$H$2 -> 2393.48 | G14: =IFERROR(DIVIDE(MINUS(E14,D14),D14),) -> 0.079584401 | H14: =VLOOKUP(M14,'NEW PTMT'!$B$4:$E1406,4,0) -> 2258 | M14: 1374-N
B15: 1375-NR | C15: Wall Mixer L Bend (Foam Flow) With Flange | D15: 1890 | E15: 2044 | F15: =H15*$H$2 -> 2043.68 | G15: =IFERROR(DIVIDE(MINUS(E15,D15),D15),) -> 0.081481481 | H15: =VLOOKUP(M15,'NEW PTMT'!$B$4:$E1406,4,0) -> 1928 | I15: 6 | J15: 24 | M15: 1375-N
B16: 144-NR | C16: Angle Cock with Flange | D16: 288.32 | E16: 312 | F16: =H16*$H$2 -> 311.64 | G16: =IFERROR(DIVIDE(MINUS(E16,D16),D16),) -> 0.082130966 | H16: =VLOOKUP(M16,'NEW PTMT'!$B$4:$E1406,4,0) -> 294 | I16: 66 | J16: 198 | M16: 144-N
B17: 145-NR | C17: 2 Way Angle Cock (Foam Flow) with Flange | D17: 538.4376 | E17: 582 | F17: =H17*$H$2 -> 580.88 | G17: =IFERROR(DIVIDE(MINUS(E17,D17),D17),) -> 0.080905197 | H17: =VLOOKUP(M17,'NEW PTMT'!$B$4:$E1406,4,0) -> 548 | I17: 35 | J17: 140 | M17: 145-N
B18: 147-NR | C18: Sink Cock Swan Neck (T/M) Square Spout (Foam Flow) with Flange | D18: 756 | E18: 814 | F18: =H18*$H$2 -> 814.08 | G18: =IFERROR(DIVIDE(MINUS(E18,D18),D18),) -> 0.076719577 | H18: =VLOOKUP(M18,'NEW PTMT'!$B$4:$E1406,4,0) -> 768 | I18: 30 | J18: 120 | M18: 147-N
B20: Novo Gold Series
B21: 123-NNG | C21: Bib Cock (Foam Flow) with Flange | D21: =D4 -> 315.88 | E21: =E4 -> 342 | G21: =IFERROR(DIVIDE(MINUS(E21,D21),D21),) -> 0.082689629 | I21: 54 | J21: 216
B22: 124-NG | C22: Long Body Bib Cock (Foam Flow) with Flange | D22: =D5 -> 383.72 | E22: =E5 -> 416 | G22: =IFERROR(DIVIDE(MINUS(E22,D22),D22),) -> 0.08412384 | I22: 33 | J22: 132
B23: 127-NG | C23: Bib Cock Nozzle with Flange | D23: =D6 -> 351.92 | E23: =E6 -> 378 | G23: =IFERROR(DIVIDE(MINUS(E23,D23),D23),) -> 0.074107752 | I23: 33 | J23: 132
